Workbook

Sheet S3a
A1: Year | B1: Station | C1: Name | D1: Sample.latitude..DM. | E1: Sample.longitude..DM. | F1: Waterdepth | G1: Class | H1: Order | I1: Family | J1: Genus | K1: Species | L1: DyntaxaID | M1: AphiaID | N1: ind.analysed.sample.fraction | O1: Pi | P1: Abundance..Ind.m2. | Q1: Relative Abundance | R1: Biomass_wet_per sample | S1: Biomass_wet_g per m2 | T1: Relative Biomass | U1: Shannon Diversity H | V1: Sample Volume (m3) | W1: Area (m2) | X1: Height (m) | Y1: Ri | Z1: Mi | AA1: Reworking_Mode | AB1: BPc_WW | AC1: BPc_max | AD1: BPc_scaled to 1* | AE1: Bti | AF1: Fti | AG1: Ipd | AH1: Ipc_WW | AI1: IPc_max | AJ1: IPc_scaled to 1* | AM1: Notes
A2: 2020 | B2: GF_H | C2: SALTKÄLLA | D2: 58 24.12 | E2: 11 37.62 | F2: 44 | G2: Ophiuroidea | H2: Ophiurida | I2: Amphiuridae | J2: Amphiura | K2: Amphiura sp. | L2: 1004764 | M2: 123613 | N2: 15 | O2: =N2/$N$29 -> 0.096153846 | P2: 150 | Q2: =P2/$P$29 -> 0.096153846 | R2: 6.92 | S2: =R2*10 -> 69.2 | T2: =S2/$S$29 -> 0.31627057 | U2: =O2*LN(O2) -> -0.22517364 | V2: =16.3/1000 -> 0.0163 | W2: 0.1 | X2: =V2/W2 -> 0.163 | Y2: 4 | Z2: 3 | AA2: B | AB2: =(SQRT(S2/P2))*P2*Z2*Y2 -> 1222.5874 | AC2: =(SQRT(S2/P2))*P2*4*4 -> 1630.1166 | AE2: 2 | AF2: 4 | AG2: 3 | AH2: =((S2/P2)^0.75)*P2*AE2*AF2*AG2 -> 2015.179 | AI2: =((S2/P2)^0.75)*P2*4*4*4 -> 5373.8106 | AM2: Scaling to 1 for comparison of the two indices by dividing the calculated the measured BPc, IPc through the maximum possible BPc, IPc at the site
A3: 2020 | B3: GF_H | C3: SALTKÄLLA | D3: 58 24.12 | E3: 11 37.62 | F3: 44 | G3: Ophiuroidea | H3: Ophiurida | I3: Amphiuridae | J3: Amphiura | K3: Amphiura chiajei | L3: 217698 | M3: 125073 | N3: 34 | O3: =N3/$N$29 -> 0.21794872 | P3: 340 | Q3: =P3/$P$29 -> 0.21794872 | R3: 2.88 | S3: =R3*10 -> 28.8 | T3: =S3/$S$29 -> 0.13162706 | U3: =O3*LN(O3) -> -0.33204389 | V3: =16.3/1000 -> 0.0163 | W3: 0.1 | X3: =V3/W3 -> 0.163 | Y3: 4 | Z3: 3 | AA3: B | AB3: =(SQRT(S3/P3))*P3*Z3*Y3 -> 1187.4544 | AC3: =(SQRT(S3/P3))*P3*4*4 -> 1583.2726 | AE3: 2 | AF3: 4 | AG3: 3 | AH3: =((S3/P3)^0.75)*P3*AE3*AF3*AG3 -> 1281.2248 | AI3: =((S3/P3)^0.75)*P3*4*4*4 -> 3416.5995
A4: 2020 | B4: GF_H | C4: SALTKÄLLA | D4: 58 24.12 | E4: 11 37.62 | F4: 44 | G4: Ophiuroidea | H4: Ophiurida | I4: Amphiuridae | J4: Amphiura | K4: Amphiura filiformis | L4: 217699 | M4: 125080 | N4: 26 | O4: =N4/$N$29 -> 0.16666667 | P4: 260 | Q4: =P4/$P$29 -> 0.16666667 | R4: 1.43 | S4: =R4*10 -> 14.3 | T4: =S4/$S$29 -> 0.06535649 | U4: =O4*LN(O4) -> -0.29862658 | V4: =16.3/1000 -> 0.0163 | W4: 0.1 | X4: =V4/W4 -> 0.163 | Y4: 4 | Z4: 3 | AA4: B | AB4: =(SQRT(S4/P4))*P4*Z4*Y4 -> 731.70486 | AC4: =(SQRT(S4/P4))*P4*4*4 -> 975.60648 | AE4: 2 | AF4: 4 | AG4: 3 | AH4: =((S4/P4)^0.75)*P4*AE4*AF4*AG4 -> 708.69049 | AI4: =((S4/P4)^0.75)*P4*4*4*4 -> 1889.8413
A5: 2020 | B5: GF_H | C5: SALTKÄLLA | D5: 58 24.12 | E5: 11 37.62 | F5: 44 | G5: Echinoidea | H5: Spatangoida | I5: Brissidae | J5: Brissopsis | K5: Brissopsis lyrifera | L5: 217719 | M5: 124373 | N5: 1 | O5: =N5/$N$29 -> 0.0064102564 | P5: 10 | Q5: =P5/$P$29 -> 0.0064102564 | R5: 9.31 | S5: =R5*10 -> 93.1 | T5: =S5/$S$29 -> 0.42550274 | U5: =O5*LN(O5) -> -0.032370872 | V5: =16.3/1000 -> 0.0163 | W5: 0.1 | X5: =V5/W5 -> 0.163 | Y5: 4 | Z5: 3 | AA5: B | AB5: =(SQRT(S5/P5))*P5*Z5*Y5 -> 366.14751 | AC5: =(SQRT(S5/P5))*P5*4*4 -> 488.19668 | AE5: 1.38 | AF5: 3.5 | AG5: 2.5 | AH5: =((S5/P5)^0.75)*P5*AE5*AF5*AG5 -> 643.57535 | AI5: =((S5/P5)^0.75)*P5*4*4*4 -> 3411.0826
A6: 2020 | B6: GF_H | C6: SALTKÄLLA | D6: 58 24.12 | E6: 11 37.62 | F6: 44 | G6: Polychaeta | H6: Eunicida | I6: Lumbrineridae | J6: Abyssoninoe | K6: Abyssoninoe hibernica | L6: 227229 | M6: 146469 | N6: 1 | O6: =N6/$N$29 -> 0.0064102564 | P6: 10 | Q6: =P6/$P$29 -> 0.0064102564 | R6: =0.03 -> 0.03 | S6: =R6*10 -> 0.3 | T6: =S6/$S$29 -> 0.0013711152 | U6: =O6*LN(O6) -> -0.032370872 | V6: =16.3/1000 -> 0.0163 | W6: 0.1 | X6: =V6/W6 -> 0.163 | Y6: 4 | Z6: 3 | AA6: B | AB6: =(SQRT(S6/P6))*P6*Z6*Y6 -> 20.78461 | AC6: =(SQRT(S6/P6))*P6*4*4 -> 27.712813 | AE6: 1.38 | AF6: 2 | AG6: 3.5 | AH6: =((S6/P6)^0.75)*P6*AE6*AF6*AG6 -> 6.9633475 | AI6: =((S6/P6)^0.75)*P6*4*4*4 -> 46.133979
A7: 2020 | B7: GF_H | C7: SALTKÄLLA | D7: 58 24.12 | E7: 11 37.62 | F7: 44 | G7: Pilidiophora | H7: Heteronemertea | I7: Heteronemertea. familia incertae sedis | J7: Cerebratulus | K7: Cerebratulus sp. | L7: 1011282 | M7: 122348 | N7: 1 | O7: =N7/$N$29 -> 0.0064102564 | P7: 10 | Q7: =P7/$P$29 -> 0.0064102564 | R7: 0.05 | S7: =R7*10 -> 0.5 | T7: =S7/$S$29 -> 0.002285192 | U7: =O7*LN(O7) -> -0.032370872 | V7: =16.3/1000 -> 0.0163 | W7: 0.1 | X7: =V7/W7 -> 0.163 | Y7: 4 | Z7: 3 | AA7: B | AB7: =(SQRT(S7/P7))*P7*Z7*Y7 -> 26.832816 | AC7: =(SQRT(S7/P7))*P7*4*4 -> 35.777088 | AE7: 1 | AF7: 2 | AG7: 2 | AH7: =((S7/P7)^0.75)*P7*AE7*AF7*AG7 -> 4.2294851 | AI7: =((S7/P7)^0.75)*P7*4*4*4 -> 67.671761
A8: 2020 | B8: GF_H | C8: SALTKÄLLA | D8: 58 24.12 | E8: 11 37.62 | F8: 44 | G8: Polychaeta | I8: Scalibregmatidae | J8: Scalibregma | K8: Scalibregma inflatum | L8: 227839 | M8: 130980 | N8: 2 | O8: =N8/$N$29 -> 0.012820513 | P8: 20 | Q8: =P8/$P$29 -> 0.012820513 | R8: 0.005 | S8: =R8*10 -> 0.05 | T8: =S8/$S$29 -> 0.0002285192 | U8: =O8*LN(O8) -> -0.055855241 | V8: =16.3/1000 -> 0.0163 | W8: 0.1 | X8: =V8/W8 -> 0.163 | Y8: 4 | Z8: 4 | AA8: B | AB8: =(SQRT(S8/P8))*P8*Z8*Y8 -> 16 | AC8: =(SQRT(S8/P8))*P8*4*4 -> 16 | AE8: 2 | AF8: 3 | AG8: 3 | AH8: =((S8/P8)^0.75)*P8*AE8*AF8*AG8 -> 4.0249224 | AI8: =((S8/P8)^0.75)*P8*4*4*4 -> 14.310835
A9: 2020 | B9: GF_H | C9: SALTKÄLLA | D9: 58 24.12 | E9: 11 37.62 | F9: 44 | G9: Polychaeta | H9: Phyllodocida | I9: Glyceridae | J9: Glycera | K9: Glycera unicornis | L9: 226809 | M9: 130131 | N9: 1 | O9: =N9/$N$29 -> 0.0064102564 | P9: 10 | Q9: =P9/$P$29 -> 0.0064102564 | R9: 0.01 | S9: =R9*10 -> 0.1 | T9: =S9/$S$29 -> 0.00045703839 | U9: =O9*LN(O9) -> -0.032370872 | V9: =16.3/1000 -> 0.0163 | W9: 0.1 | X9: =V9/W9 -> 0.163 | Y9: 4 | Z9: 3 | AA9: B | AB9: =(SQRT(S9/P9))*P9*Z9*Y9 -> 12 | AC9: =(SQRT(S9/P9))*P9*4*4 -> 16 | AE9: 2 | AF9: 2 | AG9: 2 | AH9: =((S9/P9)^0.75)*P9*AE9*AF9*AG9 -> 2.5298221 | AI9: =((S9/P9)^0.75)*P9*4*4*4 -> 20.238577
A10: 2020 | B10: GF_H | C10: SALTKÄLLA | D10: 58 24.12 | E10: 11 37.62 | F10: 44 | K10: Nemertea | L10: 5000018 | M10: 152391 | N10: 1 | O10: =N10/$N$29 -> 0.0064102564 | P10: 10 | Q10: =P10/$P$29 -> 0.0064102564 | R10: 0.005 | S10: =R10*10 -> 0.05 | T10: =S10/$S$29 -> 0.0002285192 | U10: =O10*LN(O10) -> -0.032370872 | V10: =16.3/1000 -> 0.0163 | W10: 0.1 | X10: =V10/W10 -> 0.163 | Y10: 4 | Z10: 3 | AA10: B | AB10: =(SQRT(S10/P10))*P10*Z10*Y10 -> 8.4852814 | AC10: =(SQRT(S10/P10))*P10*4*4 -> 11.313708 | AE10: 2 | AF10: 2 | AG10: 2 | AH10: =((S10/P10)^0.75)*P10*AE10*AF10*AG10 -> 1.5042412 | AI10: =((S10/P10)^0.75)*P10*4*4*4 -> 12.03393
A11: 2020 | B11: GF_H | C11: SALTKÄLLA | D11: 58 24.12 | E11: 11 37.62 | F11: 44 | G11: Polychaeta | H11: Phyllodocida | I11: Hesionidae | J11: Oxydromus | K11: Oxydromus flexuosus | L11: 226852 | M11: 710680 | N11: 2 | O11: =N11/$N$29 -> 0.012820513 | P11: 20 | Q11: =P11/$P$29 -> 0.012820513 | R11: 0.02 | S11: =R11*10 -> 0.2 | T11: =S11/$S$29 -> 0.00091407678 | U11: =O11*LN(O11) -> -0.055855241 | V11: =16.3/1000 -> 0.0163 | W11: 0.1 | X11: =V11/W11 -> 0.163 | Y11: 4 | Z11: 3 | AA11: B | AB11: =(SQRT(S11/P11))*P11*Z11*Y11 -> 24 | AC11: =(SQRT(S11/P11))*P11*4*4 -> 32 | AE11: 1 | AF11: 2 | AG11: 1 | AH11: =((S11/P11)^0.75)*P11*AE11*AF11*AG11 -> 1.2649111 | AI11: =((S11/P11)^0.75)*P11*4*4*4 -> 40.477154
A12: 2020 | B12: GF_H | C12: SALTKÄLLA | D12: 58 24.12 | E12: 11 37.62 | F12: 44 | G12: Polychaeta | H12: Phyllodocida | I12: Pilargidae | J12: Pilargis | K12: Pilargis verrucosa | L12: 226881 | M12: 130700 | N12: 1 | O12: =N12/$N$29 -> 0.0064102564 | P12: 10 | Q12: =P12/$P$29 -> 0.0064102564 | R12: 0.01 | S12: =R12*10 -> 0.1 | T12: =S12/$S$29 -> 0.00045703839 | U12: =O12*LN(O12) -> -0.032370872 | V12: =16.3/1000 -> 0.0163 | W12: 0.1 | X12: =V12/W12 -> 0.163 | Y12: 4 | Z12: 3 | AA12: B | AB12: =(SQRT(S12/P12))*P12*Z12*Y12 -> 12 | AC12: =(SQRT(S12/P12))*P12*4*4 -> 16 | AE12: 1 | AF12: 2 | AG12: 1 | AH12: =((S12/P12)^0.75)*P12*AE12*AF12*AG12 -> 0.63245553 | AI12: =((S12/P12)^0.75)*P12*4*4*4 -> 20.238577
A13: 2020 | B13: GF_H | C13: SALTKÄLLA | D13: 58 24.12 | E13: 11 37.62 | F13: 44 | G13: Polychaeta | H13: Terebellida | I13: Terebellidae | J13: Terebellides | K13: Terebellides stroemii | L13: 227496 | M13: 131573 | N13: 5 | O13: =N13/$N$29 -> 0.032051282 | P13: 50 | Q13: =P13/$P$29 -> 0.032051282 | R13: 0.04 | S13: =R13*10 -> 0.4 | T13: =S13/$S$29 -> 0.0018281536 | U13: =O13*LN(O13) -> -0.11026981 | V13: =16.3/1000 -> 0.0163 | W13: 0.1 | X13: =V13/W13 -> 0.163 | Y13: 3 | Z13: 1 | AA13: DC | AB13: =(SQRT(S13/P13))*P13*Z13*Y13 -> 13.416408 | AC13: =(SQRT(S13/P13))*P13*4*4 -> 71.554175 | AE13: 3 | AF13: 3 | AG13: 1 | AH13: =((S13/P13)^0.75)*P13*AE13*AF13*AG13 -> 12.037325 | AI13: =((S13/P13)^0.75)*P13*4*4*4 -> 85.598759
A14: 2020 | B14: GF_H | C14: SALTKÄLLA | D14: 58 24.12 | E14: 11 37.62 | F14: 44 | G14: Polychaeta | H14: Terebellida | I14: Terebellidae | J14: Polycirrus | K14: Polycirrus plumosus | L14: 227550 | M14: 131534 | N14: 10 | O14: =N14/$N$29 -> 0.064102564 | P14: 100 | Q14: =P14/$P$29 -> 0.064102564 | R14: 0.11 | S14: =R14*10 -> 1.1 | T14: =S14/$S$29 -> 0.0050274223 | U14: =O14*LN(O14) -> -0.17610711 | V14: =16.3/1000 -> 0.0163 | W14: 0.1 | X14: =V14/W14 -> 0.163 | Y14: 3 | Z14: 1 | AA14: DC | AB14: =(SQRT(S14/P14))*P14*Z14*Y14 -> 31.464265 | AC14: =(SQRT(S14/P14))*P14*4*4 -> 167.80942 | AE14: 1 | AF14: 3 | AG14: 1 | AH14: =((S14/P14)^0.75)*P14*AE14*AF14*AG14 -> 10.189803 | AI14: =((S14/P14)^0.75)*P14*4*4*4 -> 217.38245
A15: 2020 | B15: GF_H | C15: SALTKÄLLA | D15: 58 24.12 | E15: 11 37.62 | F15: 44 | G15: Anthozoa | H15: Pennatulacea | I15: Funiculinidae | J15: Funiculina | K15: Funiculina quadrangularis | L15: 217841 | M15: 128506 | N15: 1 | O15: =N15/$N$29 -> 0.0064102564 | P15: 10 | Q15: =P15/$P$29 -> 0.0064102564 | R15: 0.43 | S15: =R15*10 -> 4.3 | T15: =S15/$S$29 -> 0.019652651 | U15: =O15*LN(O15) -> -0.032370872 | V15: =16.3/1000 -> 0.0163 | W15: 0.1 | X15: =V15/W15 -> 0.163 | Y15: 1 | Z15: 1 | AA15: E | AB15: =(SQRT(S15/P15))*P15*Z15*Y15 -> 6.5574385 | AC15: =(SQRT(S15/P15))*P15*4*4 -> 104.91902 | AE15: 1 | AF15: 1 | AG15: 1 | AH15: =((S15/P15)^0.75)*P15*AE15*AF15*AG15 -> 5.3100834 | AI15: =((S15/P15)^0.75)*P15*4*4*4 -> 339.84534
A16: 2020 | B16: GF_H | C16: SALTKÄLLA | D16: 58 24.12 | E16: 11 37.62 | F16: 44 | G16: Polycladidea | H16: Polycladida | K16: Polycladida | L16: 4000019 | M16: 2853 | N16: 1 | O16: =N16/$N$29 -> 0.0064102564 | P16: 10 | Q16: =P16/$P$29 -> 0.0064102564 | R16: 0.02 | S16: =R16*10 -> 0.2 | T16: =S16/$S$29 -> 0.00091407678 | U16: =O16*LN(O16) -> -0.032370872 | V16: =16.3/1000 -> 0.0163 | W16: 0.1 | X16: =V16/W16 -> 0.163 | Y16: 1 | Z16: 2 | AA16: E | AB16: =(SQRT(S16/P16))*P16*Z16*Y16 -> 2.8284271 | AC16: =(SQRT(S16/P16))*P16*4*4 -> 22.627417 | AE16: 1 | AF16: 2 | AG16: 1 | AH16: =((S16/P16)^0.75)*P16*AE16*AF16*AG16 -> 1.0636592 | AI16: =((S16/P16)^0.75)*P16*4*4*4 -> 34.037094
A17: 2020 | B17: GF_H | C17: SALTKÄLLA | D17: 58 24.12 | E17: 11 37.62 | F17: 44 | G17: Bivalvia | H17: Lucinida | I17: Thyasiridae | J17: Parathyasira | K17: Parathyasira equalis | L17: 218348 | M17: 954693 | N17: 6 | O17: =N17/$N$29 -> 0.038461538 | P17: 60 | Q17: =P17/$P$29 -> 0.038461538 | R17: 0.11 | S17: =R17*10 -> 1.1 | T17: =S17/$S$29 -> 0.0050274223 | U17: =O17*LN(O17) -> -0.12531141 | V17: =16.3/1000 -> 0.0163 | W17: 0.1 | X17: =V17/W17 -> 0.163 | Y17: 2 | Z17: 2 | AA17: S | AB17: =(SQRT(S17/P17))*P17*Z17*Y17 -> 32.496154 | AC17: =(SQRT(S17/P17))*P17*4*4 -> 129.98461 | AE17: 2.5 | AF17: 2 | AG17: 2.5 | AH17: =((S17/P17)^0.75)*P17*AE17*AF17*AG17 -> 37.367353 | AI17: =((S17/P17)^0.75)*P17*4*4*4 -> 191.32085
A18: 2020 | B18: GF_H | C18: SALTKÄLLA | D18: 58 24.12 | E18: 11 37.62 | F18: 44 | G18: Bivalvia | H18: Veneroida | I18: Lasaeidae | J18: Tellimya | K18: Tellimya tenella | L18: 232154 | M18: 152397 | N18: 3 | O18: =N18/$N$29 -> 0.019230769 | P18: 30 | Q18: =P18/$P$29 -> 0.019230769 | R18: 0.02 | S18: =R18*10 -> 0.2 | T18: =S18/$S$29 -> 0.00091407678 | U18: =O18*LN(O18) -> -0.075985456 | V18: =16.3/1000 -> 0.0163 | W18: 0.1 | X18: =V18/W18 -> 0.163 | Y18: 2 | Z18: 2 | AA18: S | AB18: =(SQRT(S18/P18))*P18*Z18*Y18 -> 9.797959 | AC18: =(SQRT(S18/P18))*P18*4*4 -> 39.191836 | AE18: 3 | AF18: 4 | AG18: 4 | AH18: =((S18/P18)^0.75)*P18*AE18*AF18*AG18 -> 33.596501 | AI18: =((S18/P18)^0.75)*P18*4*4*4 -> 44.795335
A19: 2020 | B19: GF_H | C19: SALTKÄLLA | D19: 58 24.12 | E19: 11 37.62 | F19: 44 | G19: Gastropoda | H19: Littorinimorpha | I19: Iravadiidae | J19: Hyala | K19: Hyala vitrea | L19: 217978 | M19: 140129 | N19: 23 | O19: =N19/$N$29 -> 0.1474359 | P19: 230 | Q19: =P19/$P$29 -> 0.1474359 | R19: 0.06 | S19: =R19*10 -> 0.6 | T19: =S19/$S$29 -> 0.0027422303 | U19: =O19*LN(O19) -> -0.28224565 | V19: =16.3/1000 -> 0.0163 | W19: 0.1 | X19: =V19/W19 -> 0.163 | Y19: 2 | Z19: 3 | AA19: S | AB19: =(SQRT(S19/P19))*P19*Z19*Y19 -> 70.484041 | AC19: =(SQRT(S19/P19))*P19*4*4 -> 187.95744 | AE19: 1 | AF19: 3 | AG19: 1 | AH19: =((S19/P19)^0.75)*P19*AE19*AF19*AG19 -> 7.9646492 | AI19: =((S19/P19)^0.75)*P19*4*4*4 -> 169.91252
A20: 2020 | B20: GF_H | C20: SALTKÄLLA | D20: 58 24.12 | E20: 11 37.62 | F20: 44 | G20: Gastropoda | H20: Cephalaspidea | I20: Cylichnidae | J20: Cylichna | K20: Cylichna cylindracea | L20: 218099 | M20: 139476 | N20: 2 | O20: =N20/$N$29 -> 0.012820513 | P20: 20 | Q20: =P20/$P$29 -> 0.012820513 | R20: 0.01 | S20: =R20*10 -> 0.1 | T20: =S20/$S$29 -> 0.00045703839 | U20: =O20*LN(O20) -> -0.055855241 | V20: =16.3/1000 -> 0.0163 | W20: 0.1 | X20: =V20/W20 -> 0.163 | Y20: 2 | Z20: 3 | AA20: S | AB20: =(SQRT(S20/P20))*P20*Z20*Y20 -> 8.4852814 | AC20: =(SQRT(S20/P20))*P20*4*4 -> 22.627417 | AE20: 3 | AF20: 2 | AG20: 2 | AH20: =((S20/P20)^0.75)*P20*AE20*AF20*AG20 -> 4.5127237 | AI20: =((S20/P20)^0.75)*P20*4*4*4 -> 24.06786
A21: 2020 | B21: GF_H | C21: SALTKÄLLA | D21: 58 24.12 | E21: 11 37.62 | F21: 44 | G21: Malacostraca | H21: Cumacea | I21: Diastylidae | J21: Diastylis | K21: Diastylis rugosa | L21: 233416 | M21: 110488 | N21: 1 | O21: =N21/$N$29 -> 0.0064102564 | P21: 10 | Q21: =P21/$P$29 -> 0.0064102564 | R21: 0.005 | S21: =R21*10 -> 0.05 | T21: =S21/$S$29 -> 0.0002285192 | U21: =O21*LN(O21) -> -0.032370872 | V21: =16.3/1000 -> 0.0163 | W21: 0.1 | X21: =V21/W21 -> 0.163 | Y21: 2 | Z21: 3 | AA21: S | AB21: =(SQRT(S21/P21))*P21*Z21*Y21 -> 4.2426407 | AC21: =(SQRT(S21/P21))*P21*4*4 -> 11.313708 | AE21: 3 | AF21: 2 | AG21: 1 | AH21: =((S21/P21)^0.75)*P21*AE21*AF21*AG21 -> 1.1281809 | AI21: =((S21/P21)^0.75)*P21*4*4*4 -> 12.03393
A22: 2020 | B22: GF_H | C22: SALTKÄLLA | D22: 58 24.12 | E22: 11 37.62 | F22: 44 | G22: Polychaeta | H22: Phyllodocida | I22: Sigalionidae | J22: Pholoe | K22: Pholoe pallida | L22: 227135 | M22: 130604 | N22: 1 | O22: =N22/$N$29 -> 0.0064102564 | P22: 10 | Q22: =P22/$P$29 -> 0.0064102564 | R22: 0.005 | S22: =R22*10 -> 0.05 | T22: =S22/$S$29 -> 0.0002285192 | U22: =O22*LN(O22) -> -0.032370872 | V22: =16.3/1000 -> 0.0163 | W22: 0.1 | X22: =V22/W22 -> 0.163 | Y22: 2 | Z22: 2 | AA22: S | AB22: =(SQRT(S22/P22))*P22*Z22*Y22 -> 2.8284271 | AC22: =(SQRT(S22/P22))*P22*4*4 -> 11.313708 | AE22: 1 | AF22: 2 | AG22: 1 | AH22: =((S22/P22)^0.75)*P22*AE22*AF22*AG22 -> 0.37606031 | AI22: =((S22/P22)^0.75)*P22*4*4*4 -> 12.03393
A23: 2020 | B23: GF_H | C23: SALTKÄLLA | D23: 58 24.12 | E23: 11 37.62 | F23: 44 | G23: Polychaeta | I23: Maldanidae | J23: Rhodine | K23: Rhodine loveni | L23: 227806 | M23: 130331 | N23: 6 | O23: =N23/$N$29 -> 0.038461538 | P23: 60 | Q23: =P23/$P$29 -> 0.038461538 | R23: 0.32 | S23: =R23*10 -> 3.2 | T23: =S23/$S$29 -> 0.014625229 | U23: =O23*LN(O23) -> -0.12531141 | V23: =16.3/1000 -> 0.0163 | W23: 0.1 | X23: =V23/W23 -> 0.163 | Y23: 3 | Z23: 1 | AA23: UC | AB23: =(SQRT(S23/P23))*P23*Z23*Y23 -> 41.569219 | AC23: =(SQRT(S23/P23))*P23*4*4 -> 221.7025 | AE23: 3 | AF23: 4 | AG23: 2.71 | AH23: =((S23/P23)^0.75)*P23*AE23*AF23*AG23 -> 216.54633 | AI23: =((S23/P23)^0.75)*P23*4*4*4 -> 426.16744
A24: 2020 | B24: GF_H | C24: SALTKÄLLA | D24: 58 24.12 | E24: 11 37.62 | F24: 44 | G24: Polychaeta | H24: Terebellida | I24: Flabelligeridae | J24: Diplocirrus | K24: Diplocirrus glaucus | L24: 227394 | M24: 130100 | N24: 1 | O24: =N24/$N$29 -> 0.0064102564 | P24: 10 | Q24: =P24/$P$29 -> 0.0064102564 | R24: 0.02 | S24: =R24*10 -> 0.2 | T24: =S24/$S$29 -> 0.00091407678 | U24: =O24*LN(O24) -> -0.032370872 | V24: =16.3/1000 -> 0.0163 | W24: 0.1 | X24: =V24/W24 -> 0.163 | Y24: 3 | Z24: 2 | AA24: UC | AB24: =(SQRT(S24/P24))*P24*Z24*Y24 -> 8.4852814 | AC24: =(SQRT(S24/P24))*P24*4*4 -> 22.627417 | AE24: 1 | AF24: 3 | AG24: 2 | AH24: =((S24/P24)^0.75)*P24*AE24*AF24*AG24 -> 3.1909775 | AI24: =((S24/P24)^0.75)*P24*4*4*4 -> 34.037094
A25: 2020 | B25: GF_H | C25: SALTKÄLLA | D25: 58 24.12 | E25: 11 37.62 | F25: 44 | G25: Polychaeta | H25: Spionida | I25: Spionidae | J25: Spiophanes | K25: Spiophanes kroeyeri | L25: NA | M25: 157576 | N25: 6 | O25: =N25/$N$29 -> 0.038461538 | P25: 60 | Q25: =P25/$P$29 -> 0.038461538 | R25: 0.03 | S25: =R25*10 -> 0.3 | T25: =S25/$S$29 -> 0.0013711152 | U25: =O25*LN(O25) -> -0.12531141 | V25: =16.3/1000 -> 0.0163 | W25: 0.1 | X25: =V25/W25 -> 0.163 | Y25: 3 | Z25: 1 | AA25: UC/DC | AB25: =(SQRT(S25/P25))*P25*Z25*Y25 -> 12.727922 | AC25: =(SQRT(S25/P25))*P25*4*4 -> 67.882251 | AE25: 3 | AF25: 3 | AG25: 4 | AH25: =((S25/P25)^0.75)*P25*AE25*AF25*AG25 -> 40.614513 | AI25: =((S25/P25)^0.75)*P25*4*4*4 -> 72.203579
A26: 2020 | B26: GF_H | C26: SALTKÄLLA | D26: 58 24.12 | E26: 11 37.62 | F26: 44 | G26: Polychaeta | H26: Spionida | I26: Spionidae | J26: Prionospio | K26: Prionospio dubia | L26: 227336 | M26: 131155 | N26: 1 | O26: =N26/$N$29 -> 0.0064102564 | P26: 10 | Q26: =P26/$P$29 -> 0.0064102564 | R26: 0.02 | S26: =R26*10 -> 0.2 | T26: =S26/$S$29 -> 0.00091407678 | U26: =O26*LN(O26) -> -0.032370872 | V26: =16.3/1000 -> 0.0163 | W26: 0.1 | X26: =V26/W26 -> 0.163 | Y26: 3 | Z26: 2 | AA26: UC/DC | AB26: =(SQRT(S26/P26))*P26*Z26*Y26 -> 8.4852814 | AC26: =(SQRT(S26/P26))*P26*4*4 -> 22.627417 | AE26: 2.5 | AF26: 3 | AG26: 2 | AH26: =((S26/P26)^0.75)*P26*AE26*AF26*AG26 -> 7.9774438 | AI26: =((S26/P26)^0.75)*P26*4*4*4 -> 34.037094
A27: 2020 | B27: GF_H | C27: SALTKÄLLA | D27: 58 24.12 | E27: 11 37.62 | F27: 44 | G27: Polychaeta | H27: Spionida | I27: Spionidae | J27: Scolelepis | K27: Scolelepis korsuni | L27: 227352 | M27: 131174 | N27: 2 | O27: =N27/$N$29 -> 0.012820513 | P27: 20 | Q27: =P27/$P$29 -> 0.012820513 | R27: 0.005 | S27: =R27*10 -> 0.05 | T27: =S27/$S$29 -> 0.0002285192 | U27: =O27*LN(O27) -> -0.055855241 | V27: =16.3/1000 -> 0.0163 | W27: 0.1 | X27: =V27/W27 -> 0.163 | Y27: 3 | Z27: 2 | AA27: UC/DC | AB27: =(SQRT(S27/P27))*P27*Z27*Y27 -> 6 | AC27: =(SQRT(S27/P27))*P27*4*4 -> 16 | AE27: 3 | AF27: 3 | AG27: 3 | AH27: =((S27/P27)^0.75)*P27*AE27*AF27*AG27 -> 6.0373835 | AI27: =((S27/P27)^0.75)*P27*4*4*4 -> 14.310835
A28: 2020 | B28: GF_H | C28: SALTKÄLLA | D28: 58 24.12 | E28: 11 37.62 | F28: 44 | G28: Polychaeta | H28: Spionida | I28: Spionidae | J28: Prionospio | K28: Prionospio fallax | L28: 227337 | M28: 131157 | N28: 2 | O28: =N28/$N$29 -> 0.012820513 | P28: 20 | Q28: =P28/$P$29 -> 0.012820513 | R28: 0.005 | S28: =R28*10 -> 0.05 | T28: =S28/$S$29 -> 0.0002285192 | U28: =O28*LN(O28) -> -0.055855241 | V28: =16.3/1000 -> 0.0163 | W28: 0.1 | X28: =V28/W28 -> 0.163 | Y28: 3 | Z28: 2 | AA28: UC/DC | AB28: =(SQRT(S28/P28))*P28*Z28*Y28 -> 6 | AC28: =(SQRT(S28/P28))*P28*4*4 -> 16 | AE28: 2.5 | AF28: 3 | AG28: 2 | AH28: =((S28/P28)^0.75)*P28*AE28*AF28*AG28 -> 3.354102 | AI28: =((S28/P28)^0.75)*P28*4*4*4 -> 14.310835
N29: =SUM(N2:N28) -> 156 | O29: =SUM(O2:O28) -> 1 | P29: =SUM(P2:P28) -> 1560 | Q29: =SUM(Q2:Q28) -> 1 | R29: =SUM(R2:R28) -> 21.88 | S29: =SUM(S2:S28) -> 218.8 | T29: =SUM(T2:T28) -> 1 | U29: =-SUM(U2:U28) -> 2.544113 | Y29: 4 | Z29: 4 | AB29: =SUM(AB2:AB28) -> 3893.8657 | AC29: =SUM(AC2:AC28) -> 5968.1342 | AD29: =AB29/AC29 -> 0.65244271 | AE29: 4 | AF29: 4 | AG29: 4 | AH29: =SUM(AH2:AH28) -> 5061.0859 | AI29: =SUM(AI2:AI28) -> 16038.534 | AJ29: =AH29/AI29 -> 0.31555789
A30: 2020 | B30: GF_C | C30: ALSBÄCK | D30: 58 19.40 | E30: 11 32.80 | F30: 118 | G30: Polychaeta | I30: Scalibregmatidae | J30: Lipobranchius | K30: Lipobranchius jeffreysii | L30: 227836 | M30: 333843 | N30: 11 | O30: =N30/$N$57 -> 0.036184211 | P30: 110 | Q30: =P30/$P$57 -> 0.036184211 | R30: 1.94 | S30: =R30*10 -> 19.4 | T30: =S30/$S$57 -> 0.4033264 | U30: =O30*LN(O30) -> -0.12010019 | V30: =16.3/1000 -> 0.0163 | W30: 0.1 | X30: =V30/W30 -> 0.163 | Y30: 3.5 | Z30: 4 | AA30: B | AB30: =(SQRT(S30/P30))*P30*Z30*Y30 -> 646.73333 | AC30: =(SQRT(S30/P30))*P30*4*4 -> 739.12381 | AE30: 2.5 | AF30: 3.75 | AG30: 3.29 | AH30: =((S30/P30)^0.75)*P30*AE30*AF30*AG30 -> 923.35062 | AI30: =((S30/P30)^0.75)*P30*4*4*4 -> 1915.9291
A31: 2020 | B31: GF_C | C31: ALSBÄCK | D31: 58 19.40 | E31: 11 32.80 | F31: 118 | G31: Polychaeta | H31: Amphinomida | I31: Amphinomidae | J31: Paramphinome | K31: Paramphinome jeffreysi | L31: NA | M31: 129837 | N31: 95 | O31: =N31/$N$57 -> 0.3125 | P31: 950 | Q31: =P31/$P$57 -> 0.3125 | R31: 0.9 | S31: =R31*10 -> 9 | T31: =S31/$S$57 -> 0.18711019 | U31: =O31*LN(O31) -> -0.36348463 | V31: =16.3/1000 -> 0.0163 | W31: 0.1 | X31: =V31/W31 -> 0.163 | Y31: 4 | Z31: 3 | AA31: B | AB31: =(SQRT(S31/P31))*P31*Z31*Y31 -> 1109.5945 | AC31: =(SQRT(S31/P31))*P31*4*4 -> 1479.4594 | AE31: 3 | AF31: 2 | AG31: 1 | AH31: =((S31/P31)^0.75)*P31*AE31*AF31*AG31 -> 173.08683 | AI31: =((S31/P31)^0.75)*P31*4*4*4 -> 1846.2596
A32: 2020 | B32: GF_C | C32: ALSBÄCK | D32: 58 19.40 | E32: 11 32.80 | F32: 118 | G32: Polychaeta | I32: Scalibregmatidae | J32: Scalibregma | K32: Scalibregma inflatum | L32: 227839 | M32: 130980 | N32: 6 | O32: =N32/$N$57 -> 0.019736842 | P32: 60 | Q32: =P32/$P$57 -> 0.019736842 | R32: 0.15 | S32: =R32*10 -> 1.5 | T32: =S32/$S$57 -> 0.031185031 | U32: =O32*LN(O32) -> -0.077472399 | V32: =16.3/1000 -> 0.0163 | W32: 0.1 | X32: =V32/W32 -> 0.163 | Y32: 4 | Z32: 4 | AA32: B | AB32: =(SQRT(S32/P32))*P32*Z32*Y32 -> 151.78933 | AC32: =(SQRT(S32/P32))*P32*4*4 -> 151.78933 | AE32: 2 | AF32: 3 | AG32: 3 | AH32: =((S32/P32)^0.75)*P32*AE32*AF32*AG32 -> 67.901405 | AI32: =((S32/P32)^0.75)*P32*4*4*4 -> 241.42722
A33: 2020 | B33: GF_C | C33: ALSBÄCK | D33: 58 19.40 | E33: 11 32.80 | F33: 118 | G33: Polychaeta | H33: Phyllodocida | I33: Hesionidae | J33: Nereimyra | K33: Nereimyra woodsholea | L33: 245755 | M33: 532020 | N33: 38 | O33: =N33/$N$57 -> 0.125 | P33: 380 | Q33: =P33/$P$57 -> 0.125 | R33: 0.5 | S33: =R33*10 -> 5 | T33: =S33/$S$57 -> 0.1039501 | U33: =O33*LN(O33) -> -0.25993019 | V33: =16.3/1000 -> 0.0163 | W33: 0.1 | X33: =V33/W33 -> 0.163 | Y33: 4 | Z33: 3 | AA33: B | AB33: =(SQRT(S33/P33))*P33*Z33*Y33 -> 523.06787 | AC33: =(SQRT(S33/P33))*P33*4*4 -> 697.42383 | AE33: 1.5 | AF33: 2.2 | AG33: 1 | AH33: =((S33/P33)^0.75)*P33*AE33*AF33*AG33 -> 48.717763 | AI33: =((S33/P33)^0.75)*P33*4*4*4 -> 944.82935
A34: 2020 | B34: GF_C | C34: ALSBÄCK | D34: 58 19.40 | E34: 11 32.80 | F34: 118 | G34: Polychaeta | I34: Opheliidae | J34: Ophelina | K34: Ophelina acuminata | L34: 227825 | M34: 130500 | N34: 1 | O34: =N34/$N$57 -> 0.0032894737 | P34: 10 | Q34: =P34/$P$57 -> 0.0032894737 | R34: 0.09 | S34: =R34*10 -> 0.9 | T34: =S34/$S$57 -> 0.018711019 | U34: =O34*LN(O34) -> -0.018806012 | V34: =16.3/1000 -> 0.0163 | W34: 0.1 | X34: =V34/W34 -> 0.163 | Y34: 4 | Z34: 3 | AA34: B | AB34: =(SQRT(S34/P34))*P34*Z34*Y34 -> 36 | AC34: =(SQRT(S34/P34))*P34*4*4 -> 48 | AE34: 1 | AF34: 4 | AG34: 3 | AH34: =((S34/P34)^0.75)*P34*AE34*AF34*AG34 -> 19.718012 | AI34: =((S34/P34)^0.75)*P34*4*4*4 -> 105.16273
A35: 2020 | B35: GF_C | C35: ALSBÄCK | D35: 58 19.40 | E35: 11 32.80 | F35: 118 | K35: Nemertea | L35: 5000018 | M35: 152391 | N35: 20 | O35: =N35/$N$57 -> 0.065789474 | P35: 200 | Q35: =P35/$P$57 -> 0.065789474 | R35: 0.03 | S35: =R35*10 -> 0.3 | T35: =S35/$S$57 -> 0.0062370062 | U35: =O35*LN(O35) -> -0.17903259 | V35: =16.3/1000 -> 0.0163 | W35: 0.1 | X35: =V35/W35 -> 0.163 | Y35: 4 | Z35: 3 | AA35: B | AB35: =(SQRT(S35/P35))*P35*Z35*Y35 -> 92.9516 | AC35: =(SQRT(S35/P35))*P35*4*4 -> 123.93547 | AE35: 2 | AF35: 2 | AG35: 2 | AH35: =((S35/P35)^0.75)*P35*AE35*AF35*AG35 -> 12.195186 | AI35: =((S35/P35)^0.75)*P35*4*4*4 -> 97.561488
A36: 2020 | B36: GF_C | C36: ALSBÄCK | D36: 58 19.40 | E36: 11 32.80 | F36: 118 | G36: Bivalvia | H36: Lucinida | I36: Thyasiridae | J36: Thyasira | K36: Thyasira flexuosa | L36: 218350 | M36: 141662 | N36: 16 | O36: =N36/$N$57 -> 0.052631579 | P36: 160 | Q36: =P36/$P$57 -> 0.052631579 | R36: 0.28 | S36: =R36*10 -> 2.8 | T36: =S36/$S$57 -> 0.058212058 | U36: =O36*LN(O36) -> -0.15497047 | V36: =16.3/1000 -> 0.0163 | W36: 0.1 | X36: =V36/W36 -> 0.163 | Y36: 3 | Z36: 2 | AA36: DC | AB36: =(SQRT(S36/P36))*P36*Z36*Y36 -> 126.99606 | AC36: =(SQRT(S36/P36))*P36*4*4 -> 338.65617 | AE36: 3 | AF36: 3 | AG36: 3 | AH36: =((S36/P36)^0.75)*P36*AE36*AF36*AG36 -> 207.85586 | AI36: =((S36/P36)^0.75)*P36*4*4*4 -> 492.69538
A37: 2020 | B37: GF_C | C37: ALSBÄCK | D37: 58 19.40 | E37: 11 32.80 | F37: 118 | G37: Polychaeta | H37: Sabellida | I37: Oweniidae | J37: Galathowenia | K37: Galathowenia oculata | L37: 227556 | M37: 146950 | N37: 1 | O37: =N37/$N$57 -> 0.0032894737 | P37: 10 | Q37: =P37/$P$57 -> 0.0032894737 | R37: 0.005 | S37: =R37*10 -> 0.05 | T37: =S37/$S$57 -> 0.001039501 | U37: =O37*LN(O37) -> -0.018806012 | V37: =16.3/1000 -> 0.0163 | W37: 0.1 | X37: =V37/W37 -> 0.163 | Y37: 3 | Z37: 1 | AA37: DC | AB37: =(SQRT(S37/P37))*P37*Z37*Y37 -> 2.1213203 | AC37: =(SQRT(S37/P37))*P37*4*4 -> 11.313708 | AE37: 3 | AF37: 3 | AG37: 1 | AH37: =((S37/P37)^0.75)*P37*AE37*AF37*AG37 -> 1.6922714 | AI37: =((S37/P37)^0.75)*P37*4*4*4 -> 12.03393
A38: 2020 | B38: GF_C | C38: ALSBÄCK | D38: 58 19.40 | E38: 11 32.80 | F38: 118 | G38: Bivalvia | H38: Lucinida | I38: Thyasiridae | J38: Parathyasira | K38: Parathyasira equalis | L38: 218348 | M38: 954693 | N38: 15 | O38: =N38/$N$57 -> 0.049342105 | P38: 150 | Q38: =P38/$P$57 -> 0.049342105 | R38: 0.19 | S38: =R38*10 -> 1.9 | T38: =S38/$S$57 -> 0.03950104 | U38: =O38*LN(O38) -> -0.14846928 | V38: =16.3/1000 -> 0.0163 | W38: 0.1 | X38: =V38/W38 -> 0.163 | Y38: 2 | Z38: 2 | AA38: S | AB38: =(SQRT(S38/P38))*P38*Z38*Y38 -> 67.527772 | AC38: =(SQRT(S38/P38))*P38*4*4 -> 270.11109 | AE38: 2.5 | AF38: 2 | AG38: 2.5 | AH38: =((S38/P38)^0.75)*P38*AE38*AF38*AG38 -> 70.794257 | AI38: =((S38/P38)^0.75)*P38*4*4*4 -> 362.4666
A39: 2020 | B39: GF_C | C39: ALSBÄCK | D39: 58 19.40 | E39: 11 32.80 | F39: 118 | G39: Polychaeta | H39: Terebellida | I39: Cirratulidae | K39: Cirratulidae | L39: 2000535 | M39: 919 | N39: 35 | O39: =N39/$N$57 -> 0.11513158 | P39: 350 | Q39: =P39/$P$57 -> 0.11513158 | R39: 0.02 | S39: =R39*10 -> 0.2 | T39: =S39/$S$57 -> 0.0041580042 | U39: =O39*LN(O39) -> -0.24887759 | V39: =16.3/1000 -> 0.0163 | W39: 0.1 | X39: =V39/W39 -> 0.163 | Y39: 2 | Z39: 2 | AA39: S | AB39: =(SQRT(S39/P39))*P39*Z39*Y39 -> 33.466401 | AC39: =(SQRT(S39/P39))*P39*4*4 -> 133.8656 | AE39: 2.8333333 | AF39: 2.7333333 | AG39: 2 | AH39: =((S39/P39)^0.75)*P39*AE39*AF39*AG39 -> 20.035942 | AI39: =((S39/P39)^0.75)*P39*4*4*4 -> 82.788399
A40: 2020 | B40: GF_C | C40: ALSBÄCK | D40: 58 19.40 | E40: 11 32.80 | F40: 118 | G40: Polychaeta | H40: Terebellida | I40: Cirratulidae | J40: Tharyx | K40: Tharyx killariensis | L40: 227433 | M40: 152269 | N40: 14 | O40: =N40/$N$57 -> 0.046052632 | P40: 140 | Q40: =P40/$P$57 -> 0.046052632 | R40: 0.03 | S40: =R40*10 -> 0.3 | T40: =S40/$S$57 -> 0.0062370062 | U40: =O40*LN(O40) -> -0.14174864 | V40: =16.3/1000 -> 0.0163 | W40: 0.1 | X40: =V40/W40 -> 0.163 | Y40: 2 | Z40: 2 | AA40: S | AB40: =(SQRT(S40/P40))*P40*Z40*Y40 -> 25.922963 | AC40: =(SQRT(S40/P40))*P40*4*4 -> 103.69185 | AE40: 2.5 | AF40: 2.2 | AG40: 2 | AH40: =((S40/P40)^0.75)*P40*AE40*AF40*AG40 -> 15.337891 | AI40: =((S40/P40)^0.75)*P40*4*4*4 -> 89.238636
...

Sheet S3b
A1: Site | B1: Site | C1: Year | D1: Abundance | E1: Biomass | F1: B/A *10 | G1: SD | H1: H | I1: BPc | J1: BPc_scaled | K1: IPc | L1: Ipc_scaled | M1: BPc/IPc | N1: BPc/Ipc_scaled | O1: BPc 1 | P1: % | Q1: BPc 2 | R1: % | S1: BPc 3 | T1: % | U1: Total | V1: IPc 1 | W1: % | X1: Ipc 2 | Y1: % | Z1: Ipc 3 | AA1: % | AB1: Total
A2: Gullmarsfjord | F2: =AVERAGE(F3:F4,F6,F8:F9,F12:F14,F16:F18) -> 1.044105 | G2: =_xlfn.STDEV.P(F3:F4,F6,F8:F9,F12:F14,F16:F18) -> 1.1013101
A3: GH | B3: Saltkälla | C3: 2020 | D3: =S3a!P29 -> 1560 | E3: =S3a!S29 -> 218.8 | F3: =(E3/D3)*10 -> 1.4025641 | H3: =S3a!U29 -> 2.544113 | I3: =S3a!AB29 -> 3893.8657 | J3: =S3a!AD29 -> 0.65244271 | K3: =S3a!AH29 -> 5061.0859 | L3: =S3a!AJ29 -> 0.31555789 | M3: =I3/K3 -> 0.76937356 | N3: =J3/L3 -> 2.0675848 | O3: Amphiura sp. | P3: 0.80684517 | Q3: Brissopsis lyrifera | R3: 0.094031881 | S3: Hyala vitrea | T3: 0.018101303 | U3: 0.91897835 | V3: Amphiura sp. | W3: 0.79135078 | X3: Brissopsis lyrifera | Y3: 0.12716151 | Z3: Rhodine loveni | AA3: 0.042786536 | AB3: 0.96129883
A4: GH | B4: Saltkälla | C4: 2022 | D4: =S3a!P546 -> 1870 | E4: =S3a!S546 -> 130.4 | F4: =(E4/D4)*10 -> 0.6973262 | H4: =S3a!U546 -> 2.0865275 | I4: =S3a!AB546 -> 4501.1819 | J4: =S3a!AD546 -> 0.66668866 | K4: =S3a!AH546 -> 5514.5441 | L4: =S3a!AJ546 -> 0.37836428 | M4: =I4/K4 -> 0.81623826 | N4: =J4/L4 -> 1.7620285 | O4: Amphiura sp. | P4: 0.83311345 | Q4: Lipobranchius jeffreysii | R4: 0.03640506 | S4: Notomastus latericeus | T4: 0.017883847 | U4: 0.88740236 | V4: Amphiura sp. | W4: 0.74551975 | X4: Rhodine loveni | Y4: 0.087520505 | Z4: Lipobranchius jeffreysii | AA4: 0.070826859 | AB4: 0.90386711
A5: Average | C5: Total | D5: =AVERAGE(D3:D4) -> 1715 | E5: =AVERAGE(E3:E4) -> 174.6 | F5: =AVERAGE(F3:F4) -> 1.0499452 | G5: =_xlfn.STDEV.P(F3:F4) -> 0.35261895 | H5: =AVERAGE(H3:H4) -> 2.3153202 | I5: =AVERAGE(I3:I4) -> 4197.5238 | J5: =AVERAGE(J3:J4) -> 0.65956569 | K5: =AVERAGE(K3:K4) -> 5287.815 | L5: =AVERAGE(L3:L4) -> 0.34696109 | M5: =I5/K5 -> 0.79381063 | N5: =J5/L5 -> 1.9009788
A6: GC | B6: Alsbäck | C6: 2020 | D6: =S3a!P57 -> 3040 | E6: =S3a!S57 -> 48.1 | F6: =(E6/D6)*10 -> 0.15822368 | H6: =S3a!U57 -> 2.445297 | I6: =S3a!AB57 -> 2997.2328 | J6: =S3a!AD57 -> 0.62548981 | K6: =S3a!AH57 -> 1866.7605 | L6: =S3a!AJ57 -> 0.25864768 | M6: =I6/K6 -> 1.6055797 | N6: =J6/L6 -> 2.4183083 | O6: Paramphinome jeffreysi | P6: 0.37020632 | Q6: Lipobranchius jeffreysii | R6: 0.21577681 | S6: Nereimyra woodsholea | T6: 0.17451693 | U6: 0.76050006 | V6: Lipobranchius jeffreysii | W6: 0.49462725 | X6: Thyasira flexuosa | Y6: 0.11134576 | Z6: Paramphinome jeffreysi | AA6: 0.092720428 | AB6: 0.69869343
A7: Average | C7: 2020 | D7: =AVERAGE(D6) -> 3040 | E7: =AVERAGE(E6) -> 48.1 | F7: =(E7/D7)*10 -> 0.15822368 | H7: =AVERAGE(H6) -> 2.445297 | I7: =AVERAGE(I6) -> 2997.2328 | J7: =AVERAGE(J6) -> 0.62548981 | K7: =AVERAGE(K6) -> 1866.7605 | L7: =AVERAGE(L6) -> 0.25864768 | M7: =I7/K7 -> 1.6055797 | N7: =J7/L7 -> 2.4183083
A8: GC | B8: Alsbäck01 | C8: 2022 | D8: =S3a!P471 -> 4180 | E8: =S3a!S471 -> 129.55 | F8: =(E8/D8)*10 -> 0.30992823 | H8: =S3a!U471 -> 2.8575785 | I8: =S3a!AB471 -> 4446.3891 | J8: =S3a!AD471 -> 0.55157317 | K8: =S3a!AH471 -> 4300.6069 | L8: =S3a!AJ471 -> 0.29120488 | M8: =I8/K8 -> 1.0338981 | N8: =J8/L8 -> 1.8941069 | O8: Lipobranchius jeffreysii | P8: 0.33888305 | Q8: Paramphinome jeffreysi | R8: 0.21657918 | S8: Nereimyra woodsholea | T8: 0.087034302 | U8: 0.64249653 | V8: Lipobranchius jeffreysii | W8: 0.6330986 | X8: Thyasira sarsii | Y8: 0.060346145 | Z8: Melinna cristata | AA8: 0.05095658 | AB8: 0.74440132
A9: GC | B9: Alsbäck02 | C9: 2022 | D9: =S3a!P511 -> 4010 | E9: =S3a!S511 -> 135.8 | F9: =(E9/D9)*10 -> 0.33865337 | H9: =S3a!U511 -> 2.7885555 | I9: =S3a!AB511 -> 3843.7409 | J9: =S3a!AD511 -> 0.4456726 | K9: =S3a!AH511 -> 4666.2412 | L9: =S3a!AJ511 -> 0.29372654 | M9: =I9/K9 -> 0.82373387 | N9: =J9/L9 -> 1.5173045 | O9: Lipobranchius jeffreysii | P9: 0.24627881 | Q9: Paramphinome jeffreysi | R9: 0.14337236 | S9: Thyasira sarsii | T9: 0.0888525 | U9: 0.47850367 | V9: Lipobranchius jeffreysii | W9: 0.38739892 | X9: Thyasira sarsii | Y9: 0.12424398 | Z9: Melinna cristata | AA9: 0.11983046 | AB9: 0.63147336
A10: Average | C10: 2022 | D10: =AVERAGE(D8:D9) -> 4095 | E10: =AVERAGE(E8:E9) -> 132.675 | F10: =AVERAGE(F8:F9) -> 0.3242908 | H10: =AVERAGE(H8:H9) -> 2.823067 | I10: =AVERAGE(I8:I9) -> 4145.065 | J10: =AVERAGE(J8:J9) -> 0.49862289 | K10: =AVERAGE(K8:K9) -> 4483.424 | L10: =AVERAGE(L8:L9) -> 0.29246571 | M10: =I10/K10 -> 0.92453112 | N10: =J10/L10 -> 1.7048935
A11: Average | C11: Total | D11: =AVERAGE(D7,D10) -> 3567.5 | E11: =AVERAGE(E7,E10) -> 90.3875 | F11: =AVERAGE(F7,F10) -> 0.24125724 | G11: =_xlfn.STDEV.P(F6,F8:F9) -> 0.079158261 | H11: =AVERAGE(H7,H10) -> 2.634182 | I11: =AVERAGE(I7,I10) -> 3571.1489 | J11: =AVERAGE(J7,J10) -> 0.56205635 | K11: =AVERAGE(K7,K10) -> 3175.0923 | L11: =AVERAGE(L7,L10) -> 0.27555669 | M11: =I11/K11 -> 1.1247386 | N11: =J11/L11 -> 2.0397122
A12: GM | B12: Gullmar06 | C12: 2020 | D12: =S3a!P85 -> 1470 | E12: =S3a!S85 -> 547.25 | F12: =(E12/D12)*10 -> 3.7227891 | H12: =S3a!U85 -> 1.7213719 | I12: =S3a!AB85 -> 6512.3058 | J12: =S3a!AD85 -> 0.71652269 | K12: =S3a!AH85 -> 9781.9726 | L12: =S3a!AJ85 -> 0.31828941 | M12: =I12/K12 -> 0.66574567 | N12: =J12/L12 -> 2.2511673 | O12: Amphiura sp. | P12: 0.69330267 | Q12: Brissopsis lyrifera | R12: 0.15073858 | S12: Lipobranchius jeffreysii | T12: 0.11416101 | U12: 0.95820226 | V12: Amphiura sp. | W12: 0.58403045 | X12: Brissopsis lyrifera | Y12: 0.20422676 | Z12: Lipobranchius jeffreysii | AA12: 0.15752589 | AB12: 0.94578311
A13: GM | B13: Hagar01 | C13: 2020 | D13: =S3a!P113 -> 1610 | E13: =S3a!S113 -> 54.8 | F13: =(E13/D13)*10 -> 0.34037267 | H13: =S3a!U113 -> 2.7127054 | I13: =S3a!AB113 -> 1165.3783 | J13: =S3a!AD113 -> 0.41756417 | K13: =S3a!AH113 -> 1411.7446 | L13: =S3a!AJ113 -> 0.25417793 | M13: =I13/K13 -> 0.82548803 | N13: =J13/L13 -> 1.6428026 | O13: Amphiura sp. | P13: 0.29215429 | Q13: Nephtys incisa | R13: 0.11279892 | S13: Scalibregma inflatum | T13: 0.086832651 | U13: 0.49178587 | V13: Amphiura sp. | W13: 0.36334318 | X13: Notomastus latericeus | Y13: 0.33695536 | Z13: Magelona minuta | AA13: 0.055476412 | AB13: 0.75577495
A14: GM | B14: Hagar02 | C14: 2020 | D14: =S3a!P137 -> 990 | E14: =S3a!S137 -> 261.35 | F14: =(E14/D14)*10 -> 2.639899 | H14: =S3a!U137 -> 2.7985352 | I14: =S3a!AB137 -> 1329.3739 | J14: =S3a!AD137 -> 0.51418178 | K14: =S3a!AH137 -> 1660.1566 | L14: =S3a!AJ137 -> 0.1667039 | M14: =I14/K14 -> 0.80075211 | N14: =J14/L14 -> 3.0844016 | O14: Brissopsis lyrifera | P14: 0.44074481 | Q14: Nephtys incisa | R14: 0.17007805 | S14: Scalibregma inflatum | T14: 0.12737431 | U14: 0.73819717 | V14: Brissopsis lyrifera | W14: 0.78472549 | X14: Nephtys incisa | Y14: 0.041801171 | Z14: Scalibregma inflatum | AA14: 0.029510527 | AB14: 0.85603719
A15: Average | C15: 2020 | D15: =AVERAGE(D12:D14) -> 1356.6667 | E15: =AVERAGE(E12:E14) -> 287.8 | F15: =AVERAGE(F12:F14) -> 2.2343536 | H15: =AVERAGE(H12:H14) -> 2.4108709 | I15: =AVERAGE(I12:I14) -> 3002.3527 | J15: =AVERAGE(J12:J14) -> 0.54942288 | K15: =AVERAGE(K12:K14) -> 4284.6246 | L15: =AVERAGE(L12:L14) -> 0.24639041 | M15: =I15/K15 -> 0.70072713 | N15: =J15/L15 -> 2.2298874
A16: GM | B16: Gullmar06 | C16: 2022 | D16: =S3a!P581 -> 2830 | E16: =S3a!S581 -> 327.9 | F16: =(E16/D16)*10 -> 1.1586572 | H16: =S3a!U581 -> 1.7813467 | I16: =S3a!AB581 -> 7663.7409 | J16: =S3a!AD581 -> 0.69272959 | K16: =S3a!AH581 -> 9023.7579 | L16: =S3a!AJ581 -> 0.32971773 | M16: =I16/K16 -> 0.84928486 | N16: =J16/L16 -> 2.1009776 | O16: Amphiura sp. | P16: 0.80869756 | Q16: Brissopsis lyrifera | R16: 0.079871912 | S16: Lipobranchius jeffreysii | T16: 0.023748193 | U16: 0.91231767 | V16: Amphiura sp. | W16: 0.74837236 | X16: Brissopsis lyrifera | Y16: 0.10900971 | Z16: Rhodine loveni | AA16: 0.07114126 | AB16: 0.92852332
A17: GM | B17: Hagar01 | C17: 2022 | D17: =S3a!P611 -> 1370 | E17: =S3a!S611 -> 79.85 | F17: =(E17/D17)*10 -> 0.58284672 | H17: =S3a!U611 -> 2.6122601 | I17: =S3a!AB611 -> 1071.6246 | J17: =S3a!AD611 -> 0.41504985 | K17: =S3a!AH611 -> 1092.7896 | L17: =S3a!AJ611 -> 0.19307875 | M17: =I17/K17 -> 0.98063209 | N17: =J17/L17 -> 2.1496403 | O17: Brissopsis lyrifera | P17: 0.274064 | Q17: Amphiura sp. | R17: 0.26687798 | S17: Polycirrus plumosus | T17: 0.12073552 | U17: 0.66167751 | V17: Brissopsis lyrifera | W17: 0.42307824 | X17: Amphiura sp. | Y17: 0.2856873 | Z17: Magelona minuta | AA17: 0.069526658 | AB17: 0.7782922
A18: GM | B18: Hagar02 | C18: 2022 | D18: =S3a!P643 -> 2080 | E18: =S3a!S643 -> 27.85 | F18: =(E18/D18)*10 -> 0.13389423 | H18: =S3a!U643 -> 2.8002654 | I18: =S3a!AB643 -> 1009.4676 | J18: =S3a!AD643 -> 0.31463866 | K18: =S3a!AH643 -> 804.23833 | L18: =S3a!AJ643 -> 0.17485353 | M18: =I18/K18 -> 1.2551847 | N18: =J18/L18 -> 1.7994413 | O18: Polycirrus plumosus | P18: 0.18184308 | Q18: Scalibregma inflatum | R18: 0.16997165 | S18: Amphiura sp. | T18: 0.14655837 | U18: 0.49837311 | V18: Amphiura sp. | W18: 0.14443225 | X18: Notomastus latericeus | Y18: 0.13466825 | Z18: Magelona minuta | AA18: 0.12120272 | AB18: 0.40030321
A19: Average | C19: 2022 | D19: =AVERAGE(D16:D18) -> 2093.3333 | E19: =AVERAGE(E16:E18) -> 145.2 | F19: =AVERAGE(F16:F18) -> 0.62513273 | H19: =AVERAGE(H16:H18) -> 2.3979574 | I19: =AVERAGE(I16:I18) -> 3248.2777 | J19: =AVERAGE(J16:J18) -> 0.47413937 | K19: =AVERAGE(K16:K18) -> 3640.2619 | L19: =AVERAGE(L16:L18) -> 0.23255 | M19: =I19/K19 -> 0.89231977 | N19: =J19/L19 -> 2.0388706
A20: Average | C20: Total | D20: =AVERAGE(D15,D19) -> 1725 | E20: =AVERAGE(E15,E19) -> 216.5 | F20: =AVERAGE(F15,F19) -> 1.4297432 | G20: =_xlfn.STDEV.P(F12:F14,F16:F18) -> 1.3152446 | H20: =AVERAGE(H15,H19) -> 2.4044141 | I20: =AVERAGE(I15,I19) -> 3125.3152 | J20: =AVERAGE(J15,J19) -> 0.51178112 | K20: =AVERAGE(K15,K19) -> 3962.4433 | L20: =AVERAGE(L15,L19) -> 0.23947021 | M20: =I20/K20 -> 0.78873437 | N20: =J20/L20 -> 2.137139
A22: Hakefjord | F22: =AVERAGE(F23:F27,F29:F30) -> 0.22685608 | G22: =_xlfn.STDEV.P(F23:F27,F29:F30) -> 0.073714326
A23: HH | B23: Hökvik01 | C23: 2021 | D23: =S3a!P183 -> 3860 | E23: =S3a!S183 -> 97.4 | F23: =(E23/D23)*10 -> 0.25233161 | H23: =S3a!U183 -> 2.6477084 | I23: =S3a!AB183 -> 3514.4976 | J23: =S3a!AD183 -> 0.44231827 | K23: =S3a!AH183 -> 2609.2936 | L23: =S3a!AJ183 -> 0.19636825 | M23: =I23/K23 -> 1.3469154 | N23: =J23/L23 -> 2.2524938 | O23: Amphiura sp. | P23: 0.44275801 | Q23: Nucula nitidosa | R23: 0.14248847 | S23: Abra nitida | T23: 0.071946468 | U23: 0.65719295 | V23: Amphiura sp. | W23: 0.56888374 | X23: Nucula nitidosa | Y23: 0.089682549 | Z23: Melinna albicincta | AA23: 0.056437668 | AB23: 0.71500396
A24: HH | B24: Hökvik02 | C24: 2021 | D24: =S3a!P212 -> 5240 | E24: =S3a!S212 -> 70.95 | F24: =(E24/D24)*10 -> 0.13540076 | H24: =S3a!U212 -> 2.4235123 | I24: =S3a!AB212 -> 3866.0701 | J24: =S3a!AD212 -> 0.46448081 | K24: =S3a!AH212 -> 2433.6499 | L24: =S3a!AJ212 -> 0.20562381 | M24: =I24/K24 -> 1.5885893 | N24: =J24/L24 -> 2.2588863 | O24: Amphiura sp. | P24: 0.34979483 | Q24: Scalibregma inflatum | R24: 0.20019729 | S24: Abra nitida | T24: 0.13052907 | U24: 0.68052118 | V24: Amphiura sp. | W24: 0.52761961 | X24: Thyasira flexuosa | Y24: 0.10312024 | Z24: Kurtiella bidentata | AA24: 0.098859531 | AB24: 0.72959939
A25: HH | B25: Hökvik03 | C25: 2021 | D25: =S3a!P245 -> 4340 | E25: =S3a!S245 -> 60.95 | F25: =(E25/D25)*10 -> 0.14043779 | H25: =S3a!U245 -> 2.4649263 | I25: =S3a!AB245 -> 3733.4152 | J25: =S3a!AD245 -> 0.53958403 | K25: =S3a!AH245 -> 2405.8793 | L25: =S3a!AJ245 -> 0.24111883 | M25: =I25/K25 -> 1.5517883 | N25: =J25/L25 -> 2.2378345 | O25: Amphiura sp. | P25: 0.42500628 | Q25: Scalibregma inflatum | R25: 0.28050359 | S25: Abra nitida | T25: 0.044614727 | U25: 0.75012459 | V25: Amphiura sp. | W25: 0.60914708 | X25: Scalibregma inflatum | Y25: 0.11484505 | Z25: Thyasira flexuosa | AA25: 0.05960538 | AB25: 0.78359751
A26: HH | B26: Hökvik04 | C26: 2021 | D26: =S3a!P288 -> 5120 | E26: =S3a!S288 -> 185.25 | F26: =(E26/D26)*10 -> 0.36181641 | H26: =S3a!U288 -> 2.2909708 | I26: =S3a!AB288 -> 4530.649 | J26: =S3a!AD288 -> 0.32649938 | K26: =S3a!AH288 -> 2074.2212 | L26: =S3a!AJ288 -> 0.08326633 | M26: =I26/K26 -> 2.1842651 | N26: =J26/L26 -> 3.9211453 | O26: Abra nitida | P26: 0.42750517 | Q26: Amphiura sp. | R26: 0.16568216 | S26: Nephtys incisa | T26: 0.060860819 | U26: 0.65404815 | V26: Amphiura sp. | W26: 0.27606054 | X26: Abra nitida | Y26: 0.21238786 | Z26: Terebellides | AA26: 0.1243752 | AB26: 0.61282361
A27: HH | B27: Hökvik05 | C27: 2021 | D27: =S3a!P320 -> 4110 | E27: =S3a!S320 -> 113.8 | F27: =(E27/D27)*10 -> 0.27688564 | H27: =S3a!U320 -> 2.2359367 | I27: =S3a!AB320 -> 3037.6205 | J27: =S3a!AD320 -> 0.31633649 | K27: =S3a!AH320 -> 1416.3891 | L27: =S3a!AJ320 -> 0.087444425 | M27: =I27/K27 -> 2.144623 | N27: =J27/L27 -> 3.6175719 | O27: Abra nitida | P27: 0.45353704 | Q27: Nephtys incisa | R27: 0.11611935 | S27: Amphiura sp. | T27: 0.10451936 | U27: 0.67417575 | V27: Abra nitida | W27: 0.21513968 | X27: Notomastus latericeus | Y27: 0.13964626 | Z27: Thyasira flexuosa | AA27: 0.12730513 | AB27: 0.48209108
A28: Average | C28: Total | D28: 4534 | E28: =AVERAGE(E23:E27) -> 105.67 | F28: =AVERAGE(F23:F27) -> 0.23337444 | G28: =_xlfn.STDEV.P(F23:F27) -> 0.086006977 | H28: =AVERAGE(H23:H27) -> 2.4126109 | I28: =AVERAGE(I23:I27) -> 3736.4505 | J28: =AVERAGE(J23:J27) -> 0.41784379 | K28: =AVERAGE(K23:K27) -> 2187.8866 | L28: =AVERAGE(L23:L27) -> 0.16276433 | M28: =I28/K28 -> 1.7077898 | N28: =J28/L28 -> 2.5671706
A29: HC | B29: SK31 | C29: 2021 | D29: =S3a!P358 -> 5190 | E29: =S3a!S358 -> 102.85 | F29: =(E29/D29)*10 -> 0.19816956 | H29: =S3a!U358 -> 2.1596302 | I29: =S3a!AB358 -> 4070.1411 | J29: =S3a!AD358 -> 0.48518656 | K29: =S3a!AH358 -> 1735.0081 | L29: =S3a!AJ358 -> 0.12944597 | M29: =I29/K29 -> 2.3458917 | N29: =J29/L29 -> 3.7481783 | O29: Scalibregma inflatum | P29: 0.45683337 | Q29: Abra nitida | R29: 0.18256731 | S29: Hyala vitrea | T29: 0.07407514 | U29: 0.71347581 | V29: Scalibregma inflatum | W29: 0.3021733 | X29: Pectinaria belgica | Y29: 0.23436254 | Z29: Abra nitida | AA29: 0.10011007 | AB29: 0.6366459
A30: HC | B30: SK31 | C30: 2023 | D30: =S3a!P432 -> 4270 | E30: =S3a!S432 -> 95.2 | F30: =(E30/D30)*10 -> 0.22295082 | H30: =S3a!U432 -> 2.5860743 | I30: =S3a!AB432 -> 2746.8916 | J30: =S3a!AD432 -> 0.38278894 | K30: =S3a!AH432 -> 1755.2175 | L30: =S3a!AJ432 -> 0.14902334 | M30: =I30/K30 -> 1.5649865 | N30: =J30/L30 -> 2.568651 | O30: Amphiura sp. | P30: 0.35624645 | Q30: Abra nitida | R30: 0.12821102 | S30: Trochochaeta multisetosa | T30: 0.12696453 | U30: 0.611422 | V30: Amphiura sp. | W30: 0.45030994 | X30: Trochochaeta multisetosa | Y30: 0.20369615 | Z30: Priapulus caudatus | AA30: 0.071354175 | AB30: 0.72536027
A31: Average | C31: Total | D31: 4730 | E31: =AVERAGE(E29:E30) -> 99.025 | F31: =AVERAGE(F29:F30) -> 0.21056019 | G31: =_xlfn.STDEV.P(F29:F30) -> 0.012390631 | H31: =AVERAGE(H29:H30) -> 2.3728522 | I31: =AVERAGE(I29:I30) -> 3408.5163 | J31: =AVERAGE(J29:J30) -> 0.43398775 | K31: =AVERAGE(K29:K30) -> 1745.1128 | L31: =AVERAGE(L29:L30) -> 0.13923465 | M31: =I31/K31 -> 1.9531782 | N31: =J31/L31 -> 3.1169522
A32: HM | B32: SK31 | C32: 2021 | D32: =S3a!P358 -> 5190 | E32: =S3a!S358 -> 102.85 | F32: =(E32/D32)*10 -> 0.19816956 | H32: =S3a!U358 -> 2.1596302 | I32: =S3a!AB358 -> 4070.1411 | J32: 0.48518656 | K32: =S3a!AH358 -> 1735.0081 | L32: 0.12944597 | M32: =I32/K32 -> 2.3458917 | N32: =J32/L32 -> 3.7481783 | O32: Scalibregma inflatum | P32: 0.45683337 | Q32: Abra nitida | R32: 0.18256731 | S32: Hyala vitrea | T32: 0.07407514 | U32: 0.71347581 | V32: Scalibregma inflatum | W32: 0.3021733 | X32: Pectinaria belgica | Y32: 0.23436254 | Z32: Abra nitida | AA32: 0.10011007 | AB32: 0.6366459
A33: HM | B33: SK31 | C33: 2023 | D33: =S3a!P432 -> 4270 | E33: =S3a!S432 -> 95.2 | F33: =(E33/D33)*10 -> 0.22295082 | H33: =S3a!U432 -> 2.5860743 | I33: =S3a!AB432 -> 2746.8916 | J33: 0.38278894 | K33: =S3a!AH432 -> 1755.2175 | L33: 0.14902334 | M33: =I33/K33 -> 1.5649865 | N33: =J33/L33 -> 2.568651 | O33: Amphiura sp. | P33: 0.35624645 | Q33: Abra nitida | R33: 0.12821102 | S33: Trochochaeta multisetosa | T33: 0.12696453 | U33: 0.611422 | V33: Amphiura sp. | W33: 0.45030994 | X33: Trochochaeta multisetosa | Y33: 0.20369615 | Z33: Priapulus caudatus | AA33: 0.071354175 | AB33: 0.72536027
A34: Average | C34: Total | D34: 4730 | E34: =AVERAGE(E32:E33) -> 99.025 | F34: =AVERAGE(F32:F33) -> 0.21056019 | G34: =_xlfn.STDEV.P(F32:F33) -> 0.012390631 | H34: =AVERAGE(H32:H33) -> 2.3728522 | I34: =AVERAGE(I32:I33) -> 3408.5163 | J34: =AVERAGE(J32:J33) -> 0.43398775 | K34: =AVERAGE(K32:K33) -> 1745.1128 | L34: =AVERAGE(L32:L33) -> 0.13923465 | M34: =I34/K34 -> 1.9531782 | N34: =J34/L34 -> 3.1169522
A36: Byfjord | F36: =AVERAGE(F37:F38) -> 0.11028597 | G36: =_xlfn.STDEV.P(F37:F38) -> 0.041320454
A37: BH | B37: Byfjord08 | C37: 2023 | D37: =S3a!P374 -> 870 | E37: =S3a!S374 -> 6 | F37: =(E37/D37)*10 -> 0.068965517 | H37: =S3a!U374 -> 2.2887026 | I37: =S3a!AB374 -> 481.95963 | J37: =S3a!AD374 -> 0.53900314 | K37: =S3a!AH374 -> 160.89749 | L37: =S3a!AJ374 -> 0.14960758 | M37: =I37/K37 -> 2.9954452 | N37: =J37/L37 -> 3.6027796 | O37: Scalibregma inflatum | P37: 0.33528136 | Q37: Glycera alba | R37: 0.28169269 | S37: Nephtys incisa | T37: 0.11409858 | U37: 0.73107262 | V37: Scalibregma inflatum | W37: 0.27539046 | X37: Glycera alba | Y37: 0.21154521 | Z37: Nephtys incisa | AA37: 0.11568217 | AB37: 0.60261785
A38: BH | B38: Byfjord07 | C38: 2023 | D38: =S3a!P392 -> 2490 | E38: =S3a!S392 -> 37.75 | F38: =(E38/D38)*10 -> 0.15160643 | H38: =S3a!U392 -> 1.3656015 | I38: =S3a!AB392 -> 2691.0808 | J38: =S3a!AD392 -> 0.68979017 | K38: =S3a!AH392 -> 1005.7702 | L38: =S3a!AJ392 -> 0.17985913 | M38: =I38/K38 -> 2.6756417 | N38: =J38/L38 -> 3.835169 | O38: Scalibregma inflatum | P38: 0.82807892 | Q38: Nephtys incisa | R38: 0.061788141 | S38: Phoronis muelleri | T38: 0.03256521 | U38: 0.92243227 | V38: Scalibregma inflatum | W38: 0.73772227 | X38: Phoronis muelleri | Y38: 0.086516394 | Z38: Nephtys incisa | AA38: 0.048651744 | AB38: 0.8728904
A39: Average | C39: Total | D39: 1680 | E39: =AVERAGE(E37:E38) -> 21.875 | F39: =AVERAGE(F37:F38) -> 0.11028597 | G39: =_xlfn.STDEV.P(F37:F38) -> 0.041320454 | H39: =AVERAGE(H37:H38) -> 1.8271521 | I39: =AVERAGE(I37:I38) -> 1586.5202 | J39: =AVERAGE(J37:J38) -> 0.61439665 | K39: =AVERAGE(K37:K38) -> 583.33385 | L39: =AVERAGE(L37:L38) -> 0.16473336 | M39: =I39/K39 -> 2.7197465 | N39: =J39/L39 -> 3.7296433

Sheet S4a
A1: Sediment Reworking Analysis
A2: Relative Biomass
B3: Gullmarsfjord | M3: Average
B4: GH_2020 | C4: GH_2022 | D4: GC_2020 | E4: GC_1_2022 | F4: GC_2_2022 | G4: GM_1_2020 | H4: GM_2_2020 | I4: GM_3_2020 | J4: GM_1_2022 | K4: GM_2_2022 | L4: GM_3_2022 | M4: GH | N4: GC | O4: GM
A5: E | B5: =SUM(S3a!T15:T16) -> 0.020566728 | C5: 0 | D5: 0 | E5: 0 | F5: 0 | G5: =SUM(S3a!T69) -> 0.00036546368 | H5: =SUM(S3a!T93) -> 0.12773723 | I5: 0 | J5: 0 | K5: 0 | L5: =SUM(S3a!T622:T623) -> 0.089766607 | M5: =AVERAGE(B5:C5) -> 0.010283364 | N5: =AVERAGE(D5:F5) -> 0 | O5: =AVERAGE(G5:L5) -> 0.036311549
A6: S | B6: =SUM(S3a!T17:T22) -> 0.0095978062 | C6: =SUM(S3a!T526:T537) -> 0.014187117 | D6: =SUM(S3a!T38:T48) -> 0.062370062 | E6: =SUM(S3a!T447:T458) -> 0.12311849 | F6: =SUM(S3a!T487:T500) -> 0.18041237 | G6: =SUM(S3a!T70:T77) -> 0.0021014162 | H6: =SUM(S3a!T94:T104) -> 0.041058394 | I6: =SUM(S3a!T122:T130) -> 0.017600918 | J6: =SUM(S3a!T562:T573) -> 0.0064043916 | K6: =SUM(S3a!T593:T606) -> 0.043832185 | L6: =SUM(S3a!T624:T634) -> 0.18132855 | M6: =AVERAGE(B6:C6) -> 0.011892461 | N6: =AVERAGE(D6:F6) -> 0.12196697 | O6: =AVERAGE(G6:L6) -> 0.048720975
A7: B | B7: =SUM(S3a!T2:T12) -> 0.94469835 | C7: =SUM(S3a!T512:T523) -> 0.85506135 | D7: =SUM(S3a!T30:T35) -> 0.75051975 | E7: =SUM(S3a!T433:T441) -> 0.68313393 | F7: =SUM(S3a!T472:T482) -> 0.50441826 | G7: =SUM(S3a!T58:T64) -> 0.97359525 | H7: =SUM(S3a!T86:T90) -> 0.36040146 | I7: =SUM(S3a!T114:T118) -> 0.94451884 | J7: =SUM(S3a!T547:T558) -> 0.93183898 | K7: =SUM(S3a!T582:T589) -> 0.85410144 | L7: =SUM(S3a!T612:T615) -> 0.17773788 | M7: =AVERAGE(B7:C7) -> 0.89987985 | N7: =AVERAGE(D7:F7) -> 0.64602398 | O7: =AVERAGE(G7:L7) -> 0.70703231
A8: UC | B8: =SUM(S3a!T23:T24) -> 0.015539305 | C8: =SUM(S3a!T538:T540) -> 0.12231595 | D8: =SUM(S3a!T49:T51) -> 0.034303534 | E8: =SUM(S3a!T459:T460) -> 0.0034735623 | F8: =SUM(S3a!T501) -> 0.00036818851 | G8: =SUM(S3a!T78:T79) -> 0.018638648 | H8: =SUM(S3a!T105:T107) -> 0.26824818 | I8: =SUM(S3a!T131:T132) -> 0.00057394299 | J8: =SUM(S3a!T574:T575) -> 0.049710278 | K8: =SUM(S3a!T607) -> 0.0037570445 | L8: =SUM(S3a!T635:T638) -> 0.080789946 | M8: =AVERAGE(B8:C8) -> 0.068927628 | N8: =AVERAGE(D8:F8) -> 0.012715095 | O8: =AVERAGE(G8:L8) -> 0.070286339
A9: DC | B9: =SUM(S3a!T13:T14) -> 0.0068555759 | C9: =SUM(S3a!T524:T525) -> 0.0038343558 | D9: =SUM(S3a!T36:T37) -> 0.059251559 | E9: =SUM(S3a!T442:T446) -> 0.072558858 | F9: =SUM(S3a!T483:T486) -> 0.10198822 | G9: =SUM(S3a!T65:T68) -> 0.0013704888 | H9: =SUM(S3a!T91:T92) -> 0.15875912 | I9: =SUM(S3a!T119:T121) -> 0.035201837 | J9: =SUM(S3a!T559:T561) -> 0.0028972248 | K9: =SUM(S3a!T590:T592) -> 0.083281152 | L9: =SUM(S3a!T616:T621) -> 0.38779174 | M9: =AVERAGE(B9:C9) -> 0.0053449658 | N9: =AVERAGE(D9:F9) -> 0.077932878 | O9: =AVERAGE(G9:L9) -> 0.11155026
A10: UC/DC | B10: =SUM(S3a!T25:T28) -> 0.0027422303 | C10: =SUM(S3a!T541:T545) -> 0.004601227 | D10: =SUM(S3a!T52:T56) -> 0.093555094 | E10: =SUM(S3a!T461:T470) -> 0.11771517 | F10: =SUM(S3a!T502:T510) -> 0.21281296 | G10: =SUM(S3a!T80:T84) -> 0.0039287346 | H10: =SUM(S3a!T108:T112) -> 0.04379562 | I10: =SUM(S3a!T133:T136) -> 0.0021044576 | J10: =SUM(S3a!T576:T580) -> 0.0091491308 | K10: =SUM(S3a!T608:T610) -> 0.015028178 | L10: =SUM(S3a!T639:T642) -> 0.082585278 | M10: =AVERAGE(B10:C10) -> 0.0036717287 | N10: =AVERAGE(D10:F10) -> 0.14136107 | O10: =AVERAGE(G10:L10) -> 0.026098567
A11: BPc | M11: =S3b!$I$5 -> 4197.5238 | N11: =S3b!$I$11 -> 3571.1489 | O11: =S3b!$I$20 -> 3125.3152
A12: IPc | M12: =S3b!K5 -> 5287.815 | N12: =S3b!K11 -> 3175.0923 | O12: =S3b!K20 -> 3962.4433
A13: B/S | M13: =M7/M6 -> 75.668091 | N13: =N7/N6 -> 5.2967124 | O13: =O7/O6 -> 14.511867
A14: B+S | M14: =M7+M6 -> 0.91177231 | N14: =N7+N6 -> 0.76799095 | O14: =O7+O6 -> 0.75575328
A15: UC+DC | M15: =SUM(M8:M10) -> 0.077944323 | N15: =SUM(N8:N10) -> 0.23200905 | O15: =SUM(O8:O10) -> 0.20793517
A16: Db | M16: 20 | N16: 2.1 | O16: 3.3
A17: x.mix | M17: 11.1 | N17: 8 | O17: 7.2
A18: Irr | N18: 0.4
B19: Hakefjord | I19: Average | M19: 0.7 | N19: 1 | O19: 0.8
B20: HH_1_2021 | C20: HH_2_2021 | D20: HH_3_2021 | E20: HH_4_2021 | F20: HH_5_2021 | G20: HC_HM_2021 | H20: HC_HM_2023 | I20: HH | J20: HC | K20: HM
A21: E | B21: =SUM(S3a!T153:T155) -> 0.029774127 | C21: 0 | D21: 0 | E21: 0 | F21: 0 | G21: 0 | H21: =S3a!T405 -> 0.006302521 | I21: =AVERAGE(B21:F21) -> 0.0059548255 | J21: =AVERAGE(G21:H21) -> 0.0031512605 | K21: =AVERAGE(G21:H21) -> 0.0031512605
A22: S | B22: =SUM(S3a!T156:T175) -> 0.29106776 | C22: =SUM(S3a!T192:T206) -> 0.46511628 | D22: =SUM(S3a!T222:T240) -> 0.31747334 | E22: =SUM(S3a!T258:T281) -> 0.69932524 | F22: =SUM(S3a!T299:T312) -> 0.77811951 | G22: =SUM(S3a!T335:T352) -> 0.71657754 | H22: =SUM(S3a!T406:T425) -> 0.81407563 | I22: =AVERAGE(B22:F22) -> 0.51022042 | J22: =AVERAGE(G22:H22) -> 0.76532659 | K22: =AVERAGE(G22:H22) -> 0.76532659
A23: B | B23: =SUM(S3a!T138:T144) -> 0.42967146 | C23: =SUM(S3a!T184:T188) -> 0.48273432 | D23: =SUM(S3a!T213:T217) -> 0.55701395 | E23: =SUM(S3a!T246:T252) -> 0.16653171 | F23: =SUM(S3a!T289:T293) -> 0.12258348 | G23: =SUM(S3a!T321:T330) -> 0.12931454 | H23: =SUM(S3a!T393:T402) -> 0.15703782 | I23: =AVERAGE(B23:F23) -> 0.35170698 | J23: =AVERAGE(G23:H23) -> 0.14317618 | K23: =AVERAGE(G23:H23) -> 0.14317618
A24: UC | B24: =SUM(S3a!T176:T177) -> 0.0030800821 | C24: =SUM(S3a!T207) -> 0.00070472163 | D24: =SUM(S3a!T241:T243) -> 0.0082034454 | E24: =SUM(S3a!T282:T283) -> 0.011875843 | F24: =SUM(S3a!T313:T315) -> 0.04745167 | G24: =SUM(S3a!T353:T354) -> 0.14681575 | H24: =SUM(S3a!T426:T427) -> 0.0021008403 | I24: =AVERAGE(B24:F24) -> 0.014263152 | J24: =AVERAGE(G24:H24) -> 0.074458296 | K24: =AVERAGE(G24:H24) -> 0.074458296
A25: DC | B25: =SUM(S3a!T145:T152) -> 0.20225873 | C25: =SUM(S3a!T189:T191) -> 0.045102185 | D25: =SUM(S3a!T218:T221) -> 0.11402789 | E25: =SUM(S3a!T253:T257) -> 0.12091768 | F25: =SUM(S3a!T294:T298) -> 0.043497364 | G25: =SUM(S3a!T331:T334) -> 0.0058337385 | H25: =SUM(S3a!T403:T404) -> 0.0099789916 | I25: =AVERAGE(B25:F25) -> 0.10516077 | J25: =AVERAGE(G25:H25) -> 0.007906365 | K25: =AVERAGE(G25:H25) -> 0.007906365
A26: UC/DC | B26: =SUM(S3a!T178:T182) -> 0.044147844 | C26: =SUM(S3a!T208:T211) -> 0.0063424947 | D26: =SUM(S3a!T244) -> 0.0032813782 | E26: =SUM(S3a!T284:T287) -> 0.0013495277 | F26: =SUM(S3a!T316:T319) -> 0.0083479789 | G26: =SUM(S3a!T355:T357) -> 0.0014584346 | H26: =SUM(S3a!T428:T431) -> 0.010504202 | I26: =AVERAGE(B26:F26) -> 0.012693845 | J26: =AVERAGE(G26:H26) -> 0.0059813181 | K26: =AVERAGE(G26:H26) -> 0.0059813181
A27: BPc | I27: =S3b!I28 -> 3736.4505 | J27: =S3b!I31 -> 3408.5163 | K27: =S3b!I34 -> 3408.5163
A28: IPc | I28: =S3b!K28 -> 2187.8866 | J28: =S3b!K31 -> 1745.1128 | K28: =S3b!K34 -> 1745.1128
A29: B/S | I29: =I23/I22 -> 0.68932361 | J29: =J23/J22 -> 0.18707853 | K29: =K23/K22 -> 0.18707853
A30: B+S | I30: =I23+I22 -> 0.86192741 | J30: =J23+J22 -> 0.90850276 | K30: =K23+K22 -> 0.90850276
A31: UC+DC | I31: =SUM(I24:I26) -> 0.13211777 | J31: =SUM(J24:J26) -> 0.088345979 | K31: =SUM(K24:K26) -> 0.088345979
A32: Db | I32: 2 | J32: 3.1 | K32: 3
A33: x.mix | I33: 1.1 | J33: 5.8 | K33: 12
A34: Irr | J34: 0.5
B35: Byfjord | D35: Average | I35: 0.5 | J35: 0.6 | K35: 1
B36: BH_1_2023 | C36: BH_2_2021 | D36: BH | E36: BM | F36: BH | G36: ab | H36: biom
A37: E | B37: 0 | C37: =S3a!T380 -> 0.013245033 | D37: =AVERAGE(B37:C37) -> 0.0066225166 | E37: 0 | F37: 0 | G37: 1715 | H37: 6796.7391
A38: S | B38: =SUM(S3a!T365:T370) -> 0.16666667 | C38: =SUM(S3a!T381:T389) -> 0.5205298 | D38: =AVERAGE(B38:C38) -> 0.34359823 | E38: 0 | F38: 0 | G38: 3567.5 | H38: 3631.0902
A39: B | B39: =SUM(S3a!T359:T363) -> 0.74166667 | C39: =SUM(S3a!T375:T377) -> 0.45165563 | D39: =AVERAGE(B39:C39) -> 0.59666115 | E39: 0 | F39: 0 | G39: 1725 | H39: 8491.8935
A40: UC | B40: =SUM(S3a!T371) -> 0.0083333333 | C40: =SUM(S3a!T390) -> 0.0013245033 | D40: =AVERAGE(B40:C40) -> 0.0048289183 | E40: 0 | F40: 0 | G40: 4534 | H40: 5258.4387
...

Sheet S4b
A1: Sediment Reworking Analysis
A2: Relative Abundance
B3: Gullmarsfjord | M3: Average
B4: GH_2020 | C4: GH_2022 | D4: GC_2020 | E4: GC_1_2022 | F4: GC_2_2022 | G4: GM_1_2020 | H4: GM_2_2020 | I4: GM_3_2020 | J4: GM_1_2022 | K4: GM_2_2022 | L4: GM_3_2022 | M4: GH | N4: GC | O4: GM
A5: E | B5: =SUM(S3a!Q15:Q16) -> 0.012820513 | C5: 0 | D5: 0 | E5: 0 | F5: 0 | G5: =SUM(S3a!Q69) -> 0.0068027211 | H5: =SUM(S3a!Q93) -> 0.01863354 | I5: 0 | J5: 0 | K5: 0 | L5: =SUM(S3a!Q622:Q623) -> 0.0096153846 | M5: =AVERAGE(B5:C5) -> 0.0064102564 | N5: =AVERAGE(D5:F5) -> 0 | O5: =AVERAGE(G5:L5) -> 0.005841941
A6: S | B6: =SUM(S3a!Q17:Q22) -> 0.23076923 | C6: =SUM(S3a!Q526:Q537) -> 0.1657754 | D6: =SUM(S3a!Q38:Q48) -> 0.25657895 | E6: =SUM(S3a!Q447:Q458) -> 0.29425837 | F6: =SUM(S3a!Q487:Q500) -> 0.40399002 | G6: =SUM(S3a!Q70:Q77) -> 0.1292517 | H6: =SUM(S3a!Q94:Q104) -> 0.47204969 | I6: =SUM(S3a!Q122:Q130) -> 0.50505051 | J6: =SUM(S3a!Q562:Q573) -> 0.17314488 | K6: =SUM(S3a!Q593:Q606) -> 0.52554745 | L6: =SUM(S3a!Q624:Q634) -> 0.51442308 | M6: =AVERAGE(B6:C6) -> 0.19827232 | N6: =AVERAGE(D6:F6) -> 0.31827578 | O6: =AVERAGE(G6:L6) -> 0.38657788
A7: B | B7: =SUM(S3a!Q2:Q12) -> 0.54487179 | C7: =SUM(S3a!Q512:Q523) -> 0.64705882 | D7: =SUM(S3a!Q30:Q35) -> 0.5625 | E7: =SUM(S3a!Q433:Q441) -> 0.42583732 | F7: =SUM(S3a!Q472:Q482) -> 0.27930175 | G7: =SUM(S3a!Q58:Q64) -> 0.72108844 | H7: =SUM(S3a!Q86:Q90) -> 0.14285714 | I7: =SUM(S3a!Q114:Q118) -> 0.25252525 | J7: =SUM(S3a!Q547:Q558) -> 0.67491166 | K7: =SUM(S3a!Q582:Q589) -> 0.13868613 | L7: =SUM(S3a!Q612:Q615) -> 0.072115385 | M7: =AVERAGE(B7:C7) -> 0.59596531 | N7: =AVERAGE(D7:F7) -> 0.42254636 | O7: =AVERAGE(G7:L7) -> 0.33369733
A8: UC | B8: =SUM(S3a!Q23:Q24) -> 0.044871795 | C8: =SUM(S3a!Q538:Q540) -> 0.048128342 | D8: =SUM(S3a!Q49:Q51) -> 0.046052632 | E8: =SUM(S3a!Q459:Q460) -> 0.0215311 | F8: =SUM(S3a!Q501) -> 0.012468828 | G8: =SUM(S3a!Q78:Q79) -> 0.027210884 | H8: =SUM(S3a!Q105:Q107) -> 0.02484472 | I8: =SUM(S3a!Q131:Q132) -> 0.02020202 | J8: =SUM(S3a!Q574:Q575) -> 0.053003534 | K8: =SUM(S3a!Q607) -> 0.03649635 | L8: =SUM(S3a!Q635:Q638) -> 0.043269231 | M8: =AVERAGE(B8:C8) -> 0.046500069 | N8: =AVERAGE(D8:F8) -> 0.026684187 | O8: =AVERAGE(G8:L8) -> 0.034171123
A9: DC | B9: =SUM(S3a!Q13:Q14) -> 0.096153846 | C9: =SUM(S3a!Q524:Q525) -> 0.064171123 | D9: =SUM(S3a!Q36:Q37) -> 0.055921053 | E9: =SUM(S3a!Q442:Q446) -> 0.14354067 | F9: =SUM(S3a!Q483:Q486) -> 0.159601 | G9: =SUM(S3a!Q65:Q68) -> 0.06122449 | H9: =SUM(S3a!Q91:Q92) -> 0.086956522 | I9: =SUM(S3a!Q119:Q121) -> 0.1010101 | J9: =SUM(S3a!Q559:Q561) -> 0.03180212 | K9: =SUM(S3a!Q590:Q592) -> 0.24817518 | L9: =SUM(S3a!Q616:Q621) -> 0.25961538 | M9: =AVERAGE(B9:C9) -> 0.080162485 | N9: =AVERAGE(D9:F9) -> 0.11968757 | O9: =AVERAGE(G9:L9) -> 0.13146397
A10: UC/DC | B10: =SUM(S3a!Q25:Q28) -> 0.070512821 | C10: =SUM(S3a!Q541:Q545) -> 0.07486631 | D10: =SUM(S3a!Q52:Q56) -> 0.078947368 | E10: =SUM(S3a!Q461:Q470) -> 0.11483254 | F10: =SUM(S3a!Q502:Q510) -> 0.1446384 | G10: =SUM(S3a!Q80:Q84) -> 0.054421769 | H10: =SUM(S3a!Q108:Q112) -> 0.25465839 | I10: =SUM(S3a!Q133:Q136) -> 0.12121212 | J10: =SUM(S3a!Q576:Q580) -> 0.067137809 | K10: =SUM(S3a!Q608:Q610) -> 0.051094891 | L10: =SUM(S3a!Q639:Q642) -> 0.10096154 | M10: =AVERAGE(B10:C10) -> 0.072689565 | N10: =AVERAGE(D10:F10) -> 0.1128061 | O10: =AVERAGE(G10:L10) -> 0.10824775
B13: Hakefjord | I13: Average
B14: HH_1_2021 | C14: HH_2_2021 | D14: HH_3_2021 | E14: HH_4_2021 | F14: HH_5_2021 | G14: HC_HM_2021 | H14: HC_HM_2023 | I14: HH | J14: HC | K14: HM
A15: E | B15: =SUM(S3a!Q153:Q155) -> 0.012953368 | C15: 0 | D15: 0 | E15: 0 | F15: 0 | G15: 0 | H15: =S3a!Q405 -> 0.0023419204 | I15: =AVERAGE(B15:F15) -> 0.0025906736 | J15: =AVERAGE(G15:H15) -> 0.0011709602 | K15: =AVERAGE(G15:H15) -> 0.0011709602
A16: S | B16: =SUM(S3a!Q156:Q175) -> 0.64248705 | C16: =SUM(S3a!Q192:Q206) -> 0.62022901 | D16: =SUM(S3a!Q222:Q240) -> 0.42165899 | E16: =SUM(S3a!Q258:Q281) -> 0.70703125 | F16: =SUM(S3a!Q299:Q312) -> 0.70559611 | G16: =SUM(S3a!Q335:Q352) -> 0.52023121 | H16: =SUM(S3a!Q406:Q425) -> 0.7704918 | I16: =AVERAGE(B16:F16) -> 0.61940048 | J16: =AVERAGE(G16:H16) -> 0.64536151 | K16: =AVERAGE(G16:H16) -> 0.64536151
A17: B | B17: =SUM(S3a!Q138:Q144) -> 0.26683938 | C17: =SUM(S3a!Q184:Q188) -> 0.28244275 | D17: =SUM(S3a!Q213:Q217) -> 0.43778802 | E17: =SUM(S3a!Q246:Q252) -> 0.14257812 | F17: =SUM(S3a!Q289:Q293) -> 0.13625304 | G17: =SUM(S3a!Q321:Q330) -> 0.43737958 | H17: =SUM(S3a!Q393:Q402) -> 0.15925059 | I17: =AVERAGE(B17:F17) -> 0.25318026 | J17: =AVERAGE(G17:H17) -> 0.29831508 | K17: =AVERAGE(G17:H17) -> 0.29831508
A18: UC | B18: =SUM(S3a!Q176:Q177) -> 0.0077720207 | C18: =SUM(S3a!Q207) -> 0.0019083969 | D18: =SUM(S3a!Q241:Q243) -> 0.016129032 | E18: =SUM(S3a!Q282:Q283) -> 0.02734375 | F18: =SUM(S3a!Q313:Q315) -> 0.01946472 | G18: =SUM(S3a!Q353:Q354) -> 0.011560694 | H18: =SUM(S3a!Q426:Q427) -> 0.0070257611 | I18: =AVERAGE(B18:F18) -> 0.014523584 | J18: =AVERAGE(G18:H18) -> 0.0092932274 | K18: =AVERAGE(G18:H18) -> 0.0092932274
A19: DC | B19: =SUM(S3a!Q145:Q152) -> 0.031088083 | C19: =SUM(S3a!Q189:Q191) -> 0.076335878 | D19: =SUM(S3a!Q218:Q221) -> 0.11751152 | E19: =SUM(S3a!Q253:Q257) -> 0.10546875 | F19: =SUM(S3a!Q294:Q298) -> 0.11435523 | G19: =SUM(S3a!Q331:Q334) -> 0.021194605 | H19: =SUM(S3a!Q403:Q404) -> 0.039812646 | I19: =AVERAGE(B19:F19) -> 0.088951893 | J19: =AVERAGE(G19:H19) -> 0.030503626 | K19: =AVERAGE(G19:H19) -> 0.030503626
