Workbook

Sheet S6a
A1: site | B1: depth | C1: var | D1: val (µmol g-1) | E1: MAR (g m-2 yr-1) | F1: SD | H1: Burial rate (µmol m-2 yr-1) | I1: Burial rate (µmol m-2 d-1) Jburial | J1: Burial rate (mmol m-2 d-1)
A2: HF_H | B2: 1 | C2: rFe | D2: 135.69156
A3: HF_H | B3: 2 | C3: rFe | D3: 115.98529
A4: HF_H | B4: 3 | C4: rFe | D4: 96.508134
A5: HF_H | B5: 4 | C5: rFe | D5: 75.143526
A6: HF_H | B6: 5 | C6: rFe | D6: 81.829555
A7: HF_H | B7: 6 | C7: rFe | D7: 85.03381
A8: HF_H | B8: 7 | C8: rFe | D8: 90.695533
A9: HF_H | B9: 8 | C9: rFe | D9: 106.92277
A10: HF_H | B10: 9 | C10: rFe | D10: 88.98741
A11: HF_H | B11: 10 | C11: rFe | D11: 77.015144
A12: HF_H | B12: 11 | C12: rFe | D12: 67.105694
A13: HF_H | B13: 12 | C13: rFe | D13: 64.850543
... A17: HF_H | B17: 15 | C17: rFe | D17: 55.29477
A18: HF_H | B18: 15 | C18: rFe | D18: 67.514733 | G18: SD | H18: =(AVERAGE(D16:D18))*F19 -> 5152.3488 | I18: =H18/365 -> 14.116024 | J18: =I18/1000 -> 0.014116024
A19: HF_H | B19: Total | C19: rFe | E19: 1150 | F19: 80 | G19: Average | H19: =(AVERAGE(D16:D18))*E19 -> 74065.014 | I19: =H19/365 -> 202.91785 | J19: =I19/1000 -> 0.20291785
A20: HF_C | B20: 1 | C20: rFe | D20: 102.6422
A21: HF_C | B21: 2 | C21: rFe | D21: 109.25321
A22: HF_C | B22: 3 | C22: rFe | D22: 101.85392
A23: HF_C | B23: 4 | C23: rFe | D23: 97.744866
A24: HF_C | B24: 5 | C24: rFe | D24: 104.8727
A25: HF_C | B25: 6 | C25: rFe | D25: 114.16742
A26: HF_C | B26: 7 | C26: rFe | D26: 131.42271
A27: HF_C | B27: 8 | C27: rFe | D27: 124.70075
A28: HF_C | B28: 9 | C28: rFe | D28: 165.49023
A29: HF_C | B29: 10 | C29: rFe | D29: 139.20162
A30: HF_C | B30: 11 | C30: rFe | D30: 140.28086
A31: HF_C | B31: 12 | C31: rFe | D31: 113.27811
... A34: HF_C | B34: 14 | C34: rFe | D34: 127.53006
A35: HF_C | B35: 14 | C35: rFe | D35: 132.13413 | G35: SD | H35: =(AVERAGE(D33:D35))*F36 -> 14227.737 | I35: =H35/365 -> 38.980101 | J35: =I35/1000 -> 0.038980101
A36: HF_C | B36: Total | C36: rFe | E36: 1640 | F36: 110 | G36: Average | H36: =(AVERAGE(D33:D35))*E36 -> 212122.62 | I36: =H36/365 -> 581.15787 | J36: =I36/1000 -> 0.58115787
A37: HF_M | B37: 1 | C37: rFe | D37: 148.37982
A38: HF_M | B38: 2 | C38: rFe | D38: 122.38327
A39: HF_M | B39: 3 | C39: rFe | D39: 108.58473
A40: HF_M | B40: 4 | C40: rFe | D40: 111.81018
A41: HF_M | B41: 5 | C41: rFe | D41: 139.82781
A42: HF_M | B42: 6 | C42: rFe | D42: 109.47902
A43: HF_M | B43: 7 | C43: rFe | D43: 112.53855
A44: HF_M | B44: 8 | C44: rFe | D44: 111.97586
A45: HF_M | B45: 9 | C45: rFe | D45: 124.81739
...

Sheet S6b
A1: Burialrates (mmol m-2 d-1)
A2: Site | B2: rFe - burial | C2: SD | D2: FeS₂ - burial | E2: SD | F2: rMn - burial | G2: SD
A3: HH | B3: 0.20291785 | C3: =S6a!J18 -> 0.014116024 | D3: 0.52106027 | E3: =S6a!J163 -> 0.032164384 | F3: 0.0038220519 | G3: =S6a!J295 -> 0.00026588187
A4: HC | B4: 0.58115787 | C4: =S6a!J35 -> 0.038980101 | D4: 0.2649611 | E4: =S6a!J178 -> 0.014642557 | F4: 0.0099525796 | G4: =S6a!J313 -> 0.00066755107
A5: HM | B5: 2.0375135 | C5: =S6a!J51 -> 0.21675675 | D5: 0.7234137 | E5: =S6a!J192 -> 0.077273973 | F5: 0.053250895 | G5: =S6a!J330 -> 0.0056649888
A6: GH | B6: 0.075900937 | C6: =S6a!J115 -> 0.0090627984 | D6: 0.14378384 | E6: =S6a!J248 -> 0.014111416 | F6: 0.0011770911 | G6: =S6a!J398 -> 0.00014054819
A7: GC | B7: 0.78825823 | C7: =S6a!J131 -> 0.052550549 | D7: 0.11589041 | E7: =S6a!J262 -> 0.0078200913 | F7: 0.28321554 | G7: =S6a!J415 -> 0.018881036
A8: GM | B8: 0.69261411 | C8: =S6a!J147 -> 0.068637434 | D8: 0.47276877 | E8: =S6a!J276 -> 0.030828128 | F8: 0.018369584 | G8: =S6a!J432 -> 0.0018204093
A9: BH | B9: 0.13978513 | C9: =S6a!J66 -> 0.011896607 | D9: 0.12553507 | E9: =S6a!J205 -> 0.0083324201 | F9: 0.003222655 | G9: =S6a!J346 -> 0.00027426851
A10: BC | B10: 0.14204568 | C10: =S6a!J81 -> 0.0037380442 | D10: 0.30745644 | E10: =S6a!J218 -> 0.0067367123 | F10: 0.0010469999 | G10: =S6a!J362 -> 2.7552628e-05
A11: BM | B11: 0.29804328 | C11: =S6a!J97 -> 0.031933209 | D11: 0.40064548 | E11: =S6a!J232 -> 0.047392603 | F11: 0.002110596 | G11: =S6a!J379 -> 0.00022613528

Sheet Plots
